Workbook

Sheet DASHBOARD
B2: VALENCIA COLOURSMILE PAINT TRADING DATABASE
B3: SELECT MONTH | C3: AUGUST
B4: SELECT YEAR | C4: 2026
B5: SELECT DAY | C5: 17
B7: TOTAL SALES | F7: TOTAL PURCHASES | J7: STOCK VALUE
B8: {=IF(C3="ALL MONTH", SUMIFS(SALES!K:K, SALES!A:A, ">="&DATE(C4, 1, 1), SALES!A:A, "<="&DATE(C4, 12, 31)), IF(C5="ALL", SUMIFS(SALES!K:K, SALES!A:A, ">="&DATE(C4, MATCH(C3, {"JANUARY","FEBRUARY","MARCH","APRIL","MAY","JUNE","JULY","AUGUST","SEPTEMBER","OCTOBER","NOVEMBER","DECEMBER"}, 0), 1), SALES!A:A, "<="&EOMONTH(DATE(C4, MATCH(C3, {"JANUARY","FEBRUARY","MARCH","APRIL","MAY","JUNE","JULY","AUGUST","SEPTEMBER","OCTOBER","NOVEMBER","DECEMBER"}, 0), 1), 0)), SUMIFS(SALES!K:K, SALES!A:A, DATE(C4, MATCH(C3, {"JANUARY","FEBRUARY","MARCH","APRIL","MAY","JUNE","JULY","AUGUST","SEPTEMBER","OCTOBER","NOVEMBER","DECEMBER"}, 0), C5))))} -> 5980 | F8: {=IF(C3="ALL MONTH", SUMIFS('STOCK IN TRANSFER'!J:J, 'STOCK IN TRANSFER'!A:A, ">="&DATE(C4, 1, 1), 'STOCK IN TRANSFER'!A:A, "<="&DATE(C4, 12, 31), 'STOCK IN TRANSFER'!F:F, "STOCK IN"), IF(C5="ALL", SUMIFS('STOCK IN TRANSFER'!J:J, 'STOCK IN TRANSFER'!A:A, ">="&DATE(C4, MATCH(C3, {"JANUARY","FEBRUARY","MARCH","APRIL","MAY","JUNE","JULY","AUGUST","SEPTEMBER","OCTOBER","NOVEMBER","DECEMBER"}, 0), 1), 'STOCK IN TRANSFER'!A:A, "<="&EOMONTH(DATE(C4, MATCH(C3, {"JANUARY","FEBRUARY","MARCH","APRIL","MAY","JUNE","JULY","AUGUST","SEPTEMBER","OCTOBER","NOVEMBER","DECEMBER"}, 0), 1), 0), 'STOCK IN TRANSFER'!F:F, "STOCK IN"), SUMIFS('STOCK IN TRANSFER'!J:J, 'STOCK IN TRANSFER'!A:A, DATE(C4, MATCH(C3, {"JANUARY","FEBRUARY","MARCH","APRIL","MAY","JUNE","JULY","AUGUST","SEPTEMBER","OCTOBER","NOVEMBER","DECEMBER"}, 0), C5), 'STOCK IN TRANSFER'!F:F, "STOCK IN")))} -> 0 | J8: =SUMPRODUCT('MASTER ITEM LIST'!C2:C18, 'MASTER ITEM LIST'!E2:E18) -> 887558.98

Sheet MASTER ITEM LIST
A1: ITEM CODE | B1: DESCRIPTION | C1: COST | D1: UNIT | E1: AVAILABLE STOCKS | F1: SRP
A2: ROS-633 | B2: RAIN OR SHINE CHOCOLATE BROWN 4L | C2: 665 | D2: GALON | E2: =SUMIFS('STOCK IN TRANSFER'!G:G, 'STOCK IN TRANSFER'!E:E, B2, 'STOCK IN TRANSFER'!F:F, "STOCK IN") + SUMIFS('STOCK IN TRANSFER'!G:G, 'STOCK IN TRANSFER'!E:E, B2, 'STOCK IN TRANSFER'!F:F, "ADJUSTMENT (+)") - SUMIFS('STOCK IN TRANSFER'!G:G, 'STOCK IN TRANSFER'!E:E, B2, 'STOCK IN TRANSFER'!F:F, "ADJUSTMENT (-)") - SUMIFS('STOCK IN TRANSFER'!G:G, 'STOCK IN TRANSFER'!E:E, B2, 'STOCK IN TRANSFER'!F:F, "STOCK TRANSFER") - SUMIFS(SALES!H:H, SALES!E:E, B2) -> 0
A3: ROSCB-1L | B3: RAIN OR SHINE CHOCOLATE BROWN 1L | C3: 0 | D3: LITER | E3: =SUMIFS('STOCK IN TRANSFER'!G:G, 'STOCK IN TRANSFER'!E:E, B3, 'STOCK IN TRANSFER'!F:F, "STOCK IN") + SUMIFS('STOCK IN TRANSFER'!G:G, 'STOCK IN TRANSFER'!E:E, B3, 'STOCK IN TRANSFER'!F:F, "ADJUSTMENT (+)") - SUMIFS('STOCK IN TRANSFER'!G:G, 'STOCK IN TRANSFER'!E:E, B3, 'STOCK IN TRANSFER'!F:F, "ADJUSTMENT (-)") - SUMIFS('STOCK IN TRANSFER'!G:G, 'STOCK IN TRANSFER'!E:E, B3, 'STOCK IN TRANSFER'!F:F, "STOCK TRANSFER") - SUMIFS(SALES!H:H, SALES!E:E, B3) -> 0
A4: ROS-701 | B4: RAIN OR SHINE BAGUIO GREEN 4L | C4: 665 | D4: GALON | E4: =SUMIFS('STOCK IN TRANSFER'!G:G, 'STOCK IN TRANSFER'!E:E, B4, 'STOCK IN TRANSFER'!F:F, "STOCK IN") + SUMIFS('STOCK IN TRANSFER'!G:G, 'STOCK IN TRANSFER'!E:E, B4, 'STOCK IN TRANSFER'!F:F, "ADJUSTMENT (+)") - SUMIFS('STOCK IN TRANSFER'!G:G, 'STOCK IN TRANSFER'!E:E, B4, 'STOCK IN TRANSFER'!F:F, "ADJUSTMENT (-)") - SUMIFS('STOCK IN TRANSFER'!G:G, 'STOCK IN TRANSFER'!E:E, B4, 'STOCK IN TRANSFER'!F:F, "STOCK TRANSFER") - SUMIFS(SALES!H:H, SALES!E:E, B4) -> 0
A5: POLYGTHIN-4L | B5: POLYGLOSS URETHANE THINNER 4L | C5: 675 | D5: GALON | E5: =SUMIFS('STOCK IN TRANSFER'!G:G, 'STOCK IN TRANSFER'!E:E, B5, 'STOCK IN TRANSFER'!F:F, "STOCK IN") + SUMIFS('STOCK IN TRANSFER'!G:G, 'STOCK IN TRANSFER'!E:E, B5, 'STOCK IN TRANSFER'!F:F, "ADJUSTMENT (+)") - SUMIFS('STOCK IN TRANSFER'!G:G, 'STOCK IN TRANSFER'!E:E, B5, 'STOCK IN TRANSFER'!F:F, "ADJUSTMENT (-)") - SUMIFS('STOCK IN TRANSFER'!G:G, 'STOCK IN TRANSFER'!E:E, B5, 'STOCK IN TRANSFER'!F:F, "STOCK TRANSFER") - SUMIFS(SALES!H:H, SALES!E:E, B5) -> 0
A6: PGTB-4L | B6: POLYGLOSS PU PHTHALO BLUE 4L | C6: 1883 | D6: GALON | E6: =SUMIFS('STOCK IN TRANSFER'!G:G, 'STOCK IN TRANSFER'!E:E, B6, 'STOCK IN TRANSFER'!F:F, "STOCK IN") + SUMIFS('STOCK IN TRANSFER'!G:G, 'STOCK IN TRANSFER'!E:E, B6, 'STOCK IN TRANSFER'!F:F, "ADJUSTMENT (+)") - SUMIFS('STOCK IN TRANSFER'!G:G, 'STOCK IN TRANSFER'!E:E, B6, 'STOCK IN TRANSFER'!F:F, "ADJUSTMENT (-)") - SUMIFS('STOCK IN TRANSFER'!G:G, 'STOCK IN TRANSFER'!E:E, B6, 'STOCK IN TRANSFER'!F:F, "STOCK TRANSFER") - SUMIFS(SALES!H:H, SALES!E:E, B6) -> 0
A7: PGMF-4L | B7: POLYGLOSS PU MICA RED FINE 4L | C7: 2822 | D7: GALON | E7: =SUMIFS('STOCK IN TRANSFER'!G:G, 'STOCK IN TRANSFER'!E:E, B7, 'STOCK IN TRANSFER'!F:F, "STOCK IN") + SUMIFS('STOCK IN TRANSFER'!G:G, 'STOCK IN TRANSFER'!E:E, B7, 'STOCK IN TRANSFER'!F:F, "ADJUSTMENT (+)") - SUMIFS('STOCK IN TRANSFER'!G:G, 'STOCK IN TRANSFER'!E:E, B7, 'STOCK IN TRANSFER'!F:F, "ADJUSTMENT (-)") - SUMIFS('STOCK IN TRANSFER'!G:G, 'STOCK IN TRANSFER'!E:E, B7, 'STOCK IN TRANSFER'!F:F, "STOCK TRANSFER") - SUMIFS(SALES!H:H, SALES!E:E, B7) -> 0
A8: PGMC-4L | B8: POLYGLOSS PU METALLIC COARSE 4L | C8: 1743 | D8: GALON | E8: =SUMIFS('STOCK IN TRANSFER'!G:G, 'STOCK IN TRANSFER'!E:E, B8, 'STOCK IN TRANSFER'!F:F, "STOCK IN") + SUMIFS('STOCK IN TRANSFER'!G:G, 'STOCK IN TRANSFER'!E:E, B8, 'STOCK IN TRANSFER'!F:F, "ADJUSTMENT (+)") - SUMIFS('STOCK IN TRANSFER'!G:G, 'STOCK IN TRANSFER'!E:E, B8, 'STOCK IN TRANSFER'!F:F, "ADJUSTMENT (-)") - SUMIFS('STOCK IN TRANSFER'!G:G, 'STOCK IN TRANSFER'!E:E, B8, 'STOCK IN TRANSFER'!F:F, "STOCK TRANSFER") - SUMIFS(SALES!H:H, SALES!E:E, B8) -> 0
A9: PGJB-4L | B9: POLYGLOSS PU JET BLACK 4L | C9: 1828 | D9: GALON | E9: =SUMIFS('STOCK IN TRANSFER'!G:G, 'STOCK IN TRANSFER'!E:E, B9, 'STOCK IN TRANSFER'!F:F, "STOCK IN") + SUMIFS('STOCK IN TRANSFER'!G:G, 'STOCK IN TRANSFER'!E:E, B9, 'STOCK IN TRANSFER'!F:F, "ADJUSTMENT (+)") - SUMIFS('STOCK IN TRANSFER'!G:G, 'STOCK IN TRANSFER'!E:E, B9, 'STOCK IN TRANSFER'!F:F, "ADJUSTMENT (-)") - SUMIFS('STOCK IN TRANSFER'!G:G, 'STOCK IN TRANSFER'!E:E, B9, 'STOCK IN TRANSFER'!F:F, "STOCK TRANSFER") - SUMIFS(SALES!H:H, SALES!E:E, B9) -> 0
A10: PGFB-4L | B10: POLYGLOSS PU FLAT BLACK 4L | C10: 1930 | D10: GALON | E10: =SUMIFS('STOCK IN TRANSFER'!G:G, 'STOCK IN TRANSFER'!E:E, B10, 'STOCK IN TRANSFER'!F:F, "STOCK IN") + SUMIFS('STOCK IN TRANSFER'!G:G, 'STOCK IN TRANSFER'!E:E, B10, 'STOCK IN TRANSFER'!F:F, "ADJUSTMENT (+)") - SUMIFS('STOCK IN TRANSFER'!G:G, 'STOCK IN TRANSFER'!E:E, B10, 'STOCK IN TRANSFER'!F:F, "ADJUSTMENT (-)") - SUMIFS('STOCK IN TRANSFER'!G:G, 'STOCK IN TRANSFER'!E:E, B10, 'STOCK IN TRANSFER'!F:F, "STOCK TRANSFER") - SUMIFS(SALES!H:H, SALES!E:E, B10) -> 0
A11: PGANTI-C-1L | B11: POLYGLOSS ANTI-CORROSSION | C11: 440 | D11: LITER | E11: =SUMIFS('STOCK IN TRANSFER'!G:G, 'STOCK IN TRANSFER'!E:E, B11, 'STOCK IN TRANSFER'!F:F, "STOCK IN") + SUMIFS('STOCK IN TRANSFER'!G:G, 'STOCK IN TRANSFER'!E:E, B11, 'STOCK IN TRANSFER'!F:F, "ADJUSTMENT (+)") - SUMIFS('STOCK IN TRANSFER'!G:G, 'STOCK IN TRANSFER'!E:E, B11, 'STOCK IN TRANSFER'!F:F, "ADJUSTMENT (-)") - SUMIFS('STOCK IN TRANSFER'!G:G, 'STOCK IN TRANSFER'!E:E, B11, 'STOCK IN TRANSFER'!F:F, "STOCK TRANSFER") - SUMIFS(SALES!H:H, SALES!E:E, B11) -> 3
A12: PLQDW-4L | B12: PLATONE QDE WHITE 4L | C12: 650 | D12: GAL | E12: =SUMIFS('STOCK IN TRANSFER'!G:G, 'STOCK IN TRANSFER'!E:E, B12, 'STOCK IN TRANSFER'!F:F, "STOCK IN") + SUMIFS('STOCK IN TRANSFER'!G:G, 'STOCK IN TRANSFER'!E:E, B12, 'STOCK IN TRANSFER'!F:F, "ADJUSTMENT (+)") - SUMIFS('STOCK IN TRANSFER'!G:G, 'STOCK IN TRANSFER'!E:E, B12, 'STOCK IN TRANSFER'!F:F, "ADJUSTMENT (-)") - SUMIFS('STOCK IN TRANSFER'!G:G, 'STOCK IN TRANSFER'!E:E, B12, 'STOCK IN TRANSFER'!F:F, "STOCK TRANSFER") - SUMIFS(SALES!H:H, SALES!E:E, B12) -> 0
A13: PLQDB-1L | B13: PLATONE QDE BLACK 1L | C13: 0 | D13: LITER | E13: =SUMIFS('STOCK IN TRANSFER'!G:G, 'STOCK IN TRANSFER'!E:E, B13, 'STOCK IN TRANSFER'!F:F, "STOCK IN") + SUMIFS('STOCK IN TRANSFER'!G:G, 'STOCK IN TRANSFER'!E:E, B13, 'STOCK IN TRANSFER'!F:F, "ADJUSTMENT (+)") - SUMIFS('STOCK IN TRANSFER'!G:G, 'STOCK IN TRANSFER'!E:E, B13, 'STOCK IN TRANSFER'!F:F, "ADJUSTMENT (-)") - SUMIFS('STOCK IN TRANSFER'!G:G, 'STOCK IN TRANSFER'!E:E, B13, 'STOCK IN TRANSFER'!F:F, "STOCK TRANSFER") - SUMIFS(SALES!H:H, SALES!E:E, B13) -> 0
... A80: QSHG710-5L | B80: Q-SHIELD EXTRA HG-710 GLOSS WHITE 5L | C80: 851 | D80: GAL | E80: =SUMIFS('STOCK IN TRANSFER'!G:G, 'STOCK IN TRANSFER'!E:E, B80, 'STOCK IN TRANSFER'!F:F, "STOCK IN") + SUMIFS('STOCK IN TRANSFER'!G:G, 'STOCK IN TRANSFER'!E:E, B80, 'STOCK IN TRANSFER'!F:F, "ADJUSTMENT (+)") - SUMIFS('STOCK IN TRANSFER'!G:G, 'STOCK IN TRANSFER'!E:E, B80, 'STOCK IN TRANSFER'!F:F, "ADJUSTMENT (-)") - SUMIFS('STOCK IN TRANSFER'!G:G, 'STOCK IN TRANSFER'!E:E, B80, 'STOCK IN TRANSFER'!F:F, "STOCK TRANSFER") - SUMIFS(SALES!H:H, SALES!E:E, B80) -> 12
A81: QSHG710-1L | B81: Q-SHIELD EXTRA HG-710 GLOSS WHITE 1L | D81: LITER | E81: =SUMIFS('STOCK IN TRANSFER'!G:G, 'STOCK IN TRANSFER'!E:E, B81, 'STOCK IN TRANSFER'!F:F, "STOCK IN") + SUMIFS('STOCK IN TRANSFER'!G:G, 'STOCK IN TRANSFER'!E:E, B81, 'STOCK IN TRANSFER'!F:F, "ADJUSTMENT (+)") - SUMIFS('STOCK IN TRANSFER'!G:G, 'STOCK IN TRANSFER'!E:E, B81, 'STOCK IN TRANSFER'!F:F, "ADJUSTMENT (-)") - SUMIFS('STOCK IN TRANSFER'!G:G, 'STOCK IN TRANSFER'!E:E, B81, 'STOCK IN TRANSFER'!F:F, "STOCK TRANSFER") - SUMIFS(SALES!H:H, SALES!E:E, B81) -> 0
A82: QSHG710-15L | B82: Q-SHIELD EXTRA HG-710 GLOSS WHITE 15L | C82: 2442 | D82: PAIL | E82: =SUMIFS('STOCK IN TRANSFER'!G:G, 'STOCK IN TRANSFER'!E:E, B82, 'STOCK IN TRANSFER'!F:F, "STOCK IN") + SUMIFS('STOCK IN TRANSFER'!G:G, 'STOCK IN TRANSFER'!E:E, B82, 'STOCK IN TRANSFER'!F:F, "ADJUSTMENT (+)") - SUMIFS('STOCK IN TRANSFER'!G:G, 'STOCK IN TRANSFER'!E:E, B82, 'STOCK IN TRANSFER'!F:F, "ADJUSTMENT (-)") - SUMIFS('STOCK IN TRANSFER'!G:G, 'STOCK IN TRANSFER'!E:E, B82, 'STOCK IN TRANSFER'!F:F, "STOCK TRANSFER") - SUMIFS(SALES!H:H, SALES!E:E, B82) -> 4
A83: PYLZWH-02 | B83: PYLOX LAZER WHITE 02 | C83: 95 | D83: CAN | E83: =SUMIFS('STOCK IN TRANSFER'!G:G, 'STOCK IN TRANSFER'!E:E, B83, 'STOCK IN TRANSFER'!F:F, "STOCK IN") + SUMIFS('STOCK IN TRANSFER'!G:G, 'STOCK IN TRANSFER'!E:E, B83, 'STOCK IN TRANSFER'!F:F, "ADJUSTMENT (+)") - SUMIFS('STOCK IN TRANSFER'!G:G, 'STOCK IN TRANSFER'!E:E, B83, 'STOCK IN TRANSFER'!F:F, "ADJUSTMENT (-)") - SUMIFS('STOCK IN TRANSFER'!G:G, 'STOCK IN TRANSFER'!E:E, B83, 'STOCK IN TRANSFER'!F:F, "STOCK TRANSFER") - SUMIFS(SALES!H:H, SALES!E:E, B83) -> -1
A84: PLYZVIO-20 | B84: PYLOX LAZER VIOLET 20 | C84: 95 | D84: CAN | E84: =SUMIFS('STOCK IN TRANSFER'!G:G, 'STOCK IN TRANSFER'!E:E, B84, 'STOCK IN TRANSFER'!F:F, "STOCK IN") + SUMIFS('STOCK IN TRANSFER'!G:G, 'STOCK IN TRANSFER'!E:E, B84, 'STOCK IN TRANSFER'!F:F, "ADJUSTMENT (+)") - SUMIFS('STOCK IN TRANSFER'!G:G, 'STOCK IN TRANSFER'!E:E, B84, 'STOCK IN TRANSFER'!F:F, "ADJUSTMENT (-)") - SUMIFS('STOCK IN TRANSFER'!G:G, 'STOCK IN TRANSFER'!E:E, B84, 'STOCK IN TRANSFER'!F:F, "STOCK TRANSFER") - SUMIFS(SALES!H:H, SALES!E:E, B84) -> 10
A85: PLYZSKBL-22 | B85: PYLOX LAZER SKY BLUE 22 | C85: 95 | D85: CAN | E85: =SUMIFS('STOCK IN TRANSFER'!G:G, 'STOCK IN TRANSFER'!E:E, B85, 'STOCK IN TRANSFER'!F:F, "STOCK IN") + SUMIFS('STOCK IN TRANSFER'!G:G, 'STOCK IN TRANSFER'!E:E, B85, 'STOCK IN TRANSFER'!F:F, "ADJUSTMENT (+)") - SUMIFS('STOCK IN TRANSFER'!G:G, 'STOCK IN TRANSFER'!E:E, B85, 'STOCK IN TRANSFER'!F:F, "ADJUSTMENT (-)") - SUMIFS('STOCK IN TRANSFER'!G:G, 'STOCK IN TRANSFER'!E:E, B85, 'STOCK IN TRANSFER'!F:F, "STOCK TRANSFER") - SUMIFS(SALES!H:H, SALES!E:E, B85) -> 4
A86: PLYZSIL-42 | B86: PYLOX LAZER SILVER 42 | C86: 95 | D86: CAN | E86: =SUMIFS('STOCK IN TRANSFER'!G:G, 'STOCK IN TRANSFER'!E:E, B86, 'STOCK IN TRANSFER'!F:F, "STOCK IN") + SUMIFS('STOCK IN TRANSFER'!G:G, 'STOCK IN TRANSFER'!E:E, B86, 'STOCK IN TRANSFER'!F:F, "ADJUSTMENT (+)") - SUMIFS('STOCK IN TRANSFER'!G:G, 'STOCK IN TRANSFER'!E:E, B86, 'STOCK IN TRANSFER'!F:F, "ADJUSTMENT (-)") - SUMIFS('STOCK IN TRANSFER'!G:G, 'STOCK IN TRANSFER'!E:E, B86, 'STOCK IN TRANSFER'!F:F, "STOCK TRANSFER") - SUMIFS(SALES!H:H, SALES!E:E, B86) -> 2
A87: PLYZPRGR-145 | B87: PYLOX LAZER PRIMER GRAY 145 | C87: 95 | D87: CAN | E87: =SUMIFS('STOCK IN TRANSFER'!G:G, 'STOCK IN TRANSFER'!E:E, B87, 'STOCK IN TRANSFER'!F:F, "STOCK IN") + SUMIFS('STOCK IN TRANSFER'!G:G, 'STOCK IN TRANSFER'!E:E, B87, 'STOCK IN TRANSFER'!F:F, "ADJUSTMENT (+)") - SUMIFS('STOCK IN TRANSFER'!G:G, 'STOCK IN TRANSFER'!E:E, B87, 'STOCK IN TRANSFER'!F:F, "ADJUSTMENT (-)") - SUMIFS('STOCK IN TRANSFER'!G:G, 'STOCK IN TRANSFER'!E:E, B87, 'STOCK IN TRANSFER'!F:F, "STOCK TRANSFER") - SUMIFS(SALES!H:H, SALES!E:E, B87) -> 1
A88: PLYZMTW-03 | B88: PYLOX LAZER MATT WHITE 03 | C88: 95 | D88: CAN | E88: =SUMIFS('STOCK IN TRANSFER'!G:G, 'STOCK IN TRANSFER'!E:E, B88, 'STOCK IN TRANSFER'!F:F, "STOCK IN") + SUMIFS('STOCK IN TRANSFER'!G:G, 'STOCK IN TRANSFER'!E:E, B88, 'STOCK IN TRANSFER'!F:F, "ADJUSTMENT (+)") - SUMIFS('STOCK IN TRANSFER'!G:G, 'STOCK IN TRANSFER'!E:E, B88, 'STOCK IN TRANSFER'!F:F, "ADJUSTMENT (-)") - SUMIFS('STOCK IN TRANSFER'!G:G, 'STOCK IN TRANSFER'!E:E, B88, 'STOCK IN TRANSFER'!F:F, "STOCK TRANSFER") - SUMIFS(SALES!H:H, SALES!E:E, B88) -> -7
A89: PLYZLTGR-33 | B89: PYLOX LAZER LIGHT GREEN 33 | C89: 95 | D89: CAN | E89: =SUMIFS('STOCK IN TRANSFER'!G:G, 'STOCK IN TRANSFER'!E:E, B89, 'STOCK IN TRANSFER'!F:F, "STOCK IN") + SUMIFS('STOCK IN TRANSFER'!G:G, 'STOCK IN TRANSFER'!E:E, B89, 'STOCK IN TRANSFER'!F:F, "ADJUSTMENT (+)") - SUMIFS('STOCK IN TRANSFER'!G:G, 'STOCK IN TRANSFER'!E:E, B89, 'STOCK IN TRANSFER'!F:F, "ADJUSTMENT (-)") - SUMIFS('STOCK IN TRANSFER'!G:G, 'STOCK IN TRANSFER'!E:E, B89, 'STOCK IN TRANSFER'!F:F, "STOCK TRANSFER") - SUMIFS(SALES!H:H, SALES!E:E, B89) -> 4
A90: PLYZHTRSIL-709 | B90: PYLOX LAZER HEAT RESISTANT SILVER 709 | C90: 162 | D90: CAN | E90: =SUMIFS('STOCK IN TRANSFER'!G:G, 'STOCK IN TRANSFER'!E:E, B90, 'STOCK IN TRANSFER'!F:F, "STOCK IN") + SUMIFS('STOCK IN TRANSFER'!G:G, 'STOCK IN TRANSFER'!E:E, B90, 'STOCK IN TRANSFER'!F:F, "ADJUSTMENT (+)") - SUMIFS('STOCK IN TRANSFER'!G:G, 'STOCK IN TRANSFER'!E:E, B90, 'STOCK IN TRANSFER'!F:F, "ADJUSTMENT (-)") - SUMIFS('STOCK IN TRANSFER'!G:G, 'STOCK IN TRANSFER'!E:E, B90, 'STOCK IN TRANSFER'!F:F, "STOCK TRANSFER") - SUMIFS(SALES!H:H, SALES!E:E, B90) -> 4
A91: PLYZGLD-705 | B91: PYLOX LAZER GOLD 705 | C91: 117 | D91: CAN | E91: =SUMIFS('STOCK IN TRANSFER'!G:G, 'STOCK IN TRANSFER'!E:E, B91, 'STOCK IN TRANSFER'!F:F, "STOCK IN") + SUMIFS('STOCK IN TRANSFER'!G:G, 'STOCK IN TRANSFER'!E:E, B91, 'STOCK IN TRANSFER'!F:F, "ADJUSTMENT (+)") - SUMIFS('STOCK IN TRANSFER'!G:G, 'STOCK IN TRANSFER'!E:E, B91, 'STOCK IN TRANSFER'!F:F, "ADJUSTMENT (-)") - SUMIFS('STOCK IN TRANSFER'!G:G, 'STOCK IN TRANSFER'!E:E, B91, 'STOCK IN TRANSFER'!F:F, "STOCK TRANSFER") - SUMIFS(SALES!H:H, SALES!E:E, B91) -> 1
A92: PLYZGBLK-48 | B92: PYLOX LAZER GLOSS BLACK 48 | C92: 95 | D92: CAN | E92: =SUMIFS('STOCK IN TRANSFER'!G:G, 'STOCK IN TRANSFER'!E:E, B92, 'STOCK IN TRANSFER'!F:F, "STOCK IN") + SUMIFS('STOCK IN TRANSFER'!G:G, 'STOCK IN TRANSFER'!E:E, B92, 'STOCK IN TRANSFER'!F:F, "ADJUSTMENT (+)") - SUMIFS('STOCK IN TRANSFER'!G:G, 'STOCK IN TRANSFER'!E:E, B92, 'STOCK IN TRANSFER'!F:F, "ADJUSTMENT (-)") - SUMIFS('STOCK IN TRANSFER'!G:G, 'STOCK IN TRANSFER'!E:E, B92, 'STOCK IN TRANSFER'!F:F, "STOCK TRANSFER") - SUMIFS(SALES!H:H, SALES!E:E, B92) -> 3
A93: PLYZFLOUVIO-604 | B93: PYLOX LAZER FLOURESCENT VIOLET 604 | C93: 135 | D93: CAN | E93: =SUMIFS('STOCK IN TRANSFER'!G:G, 'STOCK IN TRANSFER'!E:E, B93, 'STOCK IN TRANSFER'!F:F, "STOCK IN") + SUMIFS('STOCK IN TRANSFER'!G:G, 'STOCK IN TRANSFER'!E:E, B93, 'STOCK IN TRANSFER'!F:F, "ADJUSTMENT (+)") - SUMIFS('STOCK IN TRANSFER'!G:G, 'STOCK IN TRANSFER'!E:E, B93, 'STOCK IN TRANSFER'!F:F, "ADJUSTMENT (-)") - SUMIFS('STOCK IN TRANSFER'!G:G, 'STOCK IN TRANSFER'!E:E, B93, 'STOCK IN TRANSFER'!F:F, "STOCK TRANSFER") - SUMIFS(SALES!H:H, SALES!E:E, B93) -> 8
... A116: PLQDEY-4L | B116: PLATONE QDE YELLOW 4L | C116: 836 | D116: GAL | E116: =SUMIFS('STOCK IN TRANSFER'!G:G, 'STOCK IN TRANSFER'!E:E, B116, 'STOCK IN TRANSFER'!F:F, "STOCK IN") + SUMIFS('STOCK IN TRANSFER'!G:G, 'STOCK IN TRANSFER'!E:E, B116, 'STOCK IN TRANSFER'!F:F, "ADJUSTMENT (+)") - SUMIFS('STOCK IN TRANSFER'!G:G, 'STOCK IN TRANSFER'!E:E, B116, 'STOCK IN TRANSFER'!F:F, "ADJUSTMENT (-)") - SUMIFS('STOCK IN TRANSFER'!G:G, 'STOCK IN TRANSFER'!E:E, B116, 'STOCK IN TRANSFER'!F:F, "STOCK TRANSFER") - SUMIFS(SALES!H:H, SALES!E:E, B116) -> 0
A117: PLQDW-1L | B117: PLATONE QDE WHITE 1L | D117: LITER | E117: =SUMIFS('STOCK IN TRANSFER'!G:G, 'STOCK IN TRANSFER'!E:E, B117, 'STOCK IN TRANSFER'!F:F, "STOCK IN") + SUMIFS('STOCK IN TRANSFER'!G:G, 'STOCK IN TRANSFER'!E:E, B117, 'STOCK IN TRANSFER'!F:F, "ADJUSTMENT (+)") - SUMIFS('STOCK IN TRANSFER'!G:G, 'STOCK IN TRANSFER'!E:E, B117, 'STOCK IN TRANSFER'!F:F, "ADJUSTMENT (-)") - SUMIFS('STOCK IN TRANSFER'!G:G, 'STOCK IN TRANSFER'!E:E, B117, 'STOCK IN TRANSFER'!F:F, "STOCK TRANSFER") - SUMIFS(SALES!H:H, SALES!E:E, B117) -> 0
A118: PLQDRB-4L | B118: PLATONE QDE ROYAL BLUE 4L | C118: 698 | D118: GAL | E118: =SUMIFS('STOCK IN TRANSFER'!G:G, 'STOCK IN TRANSFER'!E:E, B118, 'STOCK IN TRANSFER'!F:F, "STOCK IN") + SUMIFS('STOCK IN TRANSFER'!G:G, 'STOCK IN TRANSFER'!E:E, B118, 'STOCK IN TRANSFER'!F:F, "ADJUSTMENT (+)") - SUMIFS('STOCK IN TRANSFER'!G:G, 'STOCK IN TRANSFER'!E:E, B118, 'STOCK IN TRANSFER'!F:F, "ADJUSTMENT (-)") - SUMIFS('STOCK IN TRANSFER'!G:G, 'STOCK IN TRANSFER'!E:E, B118, 'STOCK IN TRANSFER'!F:F, "STOCK TRANSFER") - SUMIFS(SALES!H:H, SALES!E:E, B118) -> 0
A119: PLQDLY-4L | B119: PLATONE QDE LEMON YELLOW 4L | C119: 836 | D119: GAL | E119: =SUMIFS('STOCK IN TRANSFER'!G:G, 'STOCK IN TRANSFER'!E:E, B119, 'STOCK IN TRANSFER'!F:F, "STOCK IN") + SUMIFS('STOCK IN TRANSFER'!G:G, 'STOCK IN TRANSFER'!E:E, B119, 'STOCK IN TRANSFER'!F:F, "ADJUSTMENT (+)") - SUMIFS('STOCK IN TRANSFER'!G:G, 'STOCK IN TRANSFER'!E:E, B119, 'STOCK IN TRANSFER'!F:F, "ADJUSTMENT (-)") - SUMIFS('STOCK IN TRANSFER'!G:G, 'STOCK IN TRANSFER'!E:E, B119, 'STOCK IN TRANSFER'!F:F, "STOCK TRANSFER") - SUMIFS(SALES!H:H, SALES!E:E, B119) -> 0
A120: PLQDJG-4L | B120: PLATONE QDE JADE GREEN 4L | C120: 732 | D120: GAL | E120: =SUMIFS('STOCK IN TRANSFER'!G:G, 'STOCK IN TRANSFER'!E:E, B120, 'STOCK IN TRANSFER'!F:F, "STOCK IN") + SUMIFS('STOCK IN TRANSFER'!G:G, 'STOCK IN TRANSFER'!E:E, B120, 'STOCK IN TRANSFER'!F:F, "ADJUSTMENT (+)") - SUMIFS('STOCK IN TRANSFER'!G:G, 'STOCK IN TRANSFER'!E:E, B120, 'STOCK IN TRANSFER'!F:F, "ADJUSTMENT (-)") - SUMIFS('STOCK IN TRANSFER'!G:G, 'STOCK IN TRANSFER'!E:E, B120, 'STOCK IN TRANSFER'!F:F, "STOCK TRANSFER") - SUMIFS(SALES!H:H, SALES!E:E, B120) -> 1
A121: PLQDIR-4L | B121: PLATONE QDE INTERNATIONAL RED 4L | C121: 773 | D121: GAL | E121: =SUMIFS('STOCK IN TRANSFER'!G:G, 'STOCK IN TRANSFER'!E:E, B121, 'STOCK IN TRANSFER'!F:F, "STOCK IN") + SUMIFS('STOCK IN TRANSFER'!G:G, 'STOCK IN TRANSFER'!E:E, B121, 'STOCK IN TRANSFER'!F:F, "ADJUSTMENT (+)") - SUMIFS('STOCK IN TRANSFER'!G:G, 'STOCK IN TRANSFER'!E:E, B121, 'STOCK IN TRANSFER'!F:F, "ADJUSTMENT (-)") - SUMIFS('STOCK IN TRANSFER'!G:G, 'STOCK IN TRANSFER'!E:E, B121, 'STOCK IN TRANSFER'!F:F, "STOCK TRANSFER") - SUMIFS(SALES!H:H, SALES!E:E, B121) -> 3
A122: PLQDG-4L | B122: PLATONE QDE GREEN 4L | C122: 1593 | D122: GALON | E122: =SUMIFS('STOCK IN TRANSFER'!G:G, 'STOCK IN TRANSFER'!E:E, B122, 'STOCK IN TRANSFER'!F:F, "STOCK IN") + SUMIFS('STOCK IN TRANSFER'!G:G, 'STOCK IN TRANSFER'!E:E, B122, 'STOCK IN TRANSFER'!F:F, "ADJUSTMENT (+)") - SUMIFS('STOCK IN TRANSFER'!G:G, 'STOCK IN TRANSFER'!E:E, B122, 'STOCK IN TRANSFER'!F:F, "ADJUSTMENT (-)") - SUMIFS('STOCK IN TRANSFER'!G:G, 'STOCK IN TRANSFER'!E:E, B122, 'STOCK IN TRANSFER'!F:F, "STOCK TRANSFER") - SUMIFS(SALES!H:H, SALES!E:E, B122) -> 1
A123: PLQDCB-4L | B123: PLATONE QDE CHOCOLATE BROWN 4L | C123: 668 | D123: GAL | E123: =SUMIFS('STOCK IN TRANSFER'!G:G, 'STOCK IN TRANSFER'!E:E, B123, 'STOCK IN TRANSFER'!F:F, "STOCK IN") + SUMIFS('STOCK IN TRANSFER'!G:G, 'STOCK IN TRANSFER'!E:E, B123, 'STOCK IN TRANSFER'!F:F, "ADJUSTMENT (+)") - SUMIFS('STOCK IN TRANSFER'!G:G, 'STOCK IN TRANSFER'!E:E, B123, 'STOCK IN TRANSFER'!F:F, "ADJUSTMENT (-)") - SUMIFS('STOCK IN TRANSFER'!G:G, 'STOCK IN TRANSFER'!E:E, B123, 'STOCK IN TRANSFER'!F:F, "STOCK TRANSFER") - SUMIFS(SALES!H:H, SALES!E:E, B123) -> 2
A124: PLQDB-4L | B124: PLATONE QDE BLACK 4L | C124: 661 | D124: GAL | E124: =SUMIFS('STOCK IN TRANSFER'!G:G, 'STOCK IN TRANSFER'!E:E, B124, 'STOCK IN TRANSFER'!F:F, "STOCK IN") + SUMIFS('STOCK IN TRANSFER'!G:G, 'STOCK IN TRANSFER'!E:E, B124, 'STOCK IN TRANSFER'!F:F, "ADJUSTMENT (+)") - SUMIFS('STOCK IN TRANSFER'!G:G, 'STOCK IN TRANSFER'!E:E, B124, 'STOCK IN TRANSFER'!F:F, "ADJUSTMENT (-)") - SUMIFS('STOCK IN TRANSFER'!G:G, 'STOCK IN TRANSFER'!E:E, B124, 'STOCK IN TRANSFER'!F:F, "STOCK TRANSFER") - SUMIFS(SALES!H:H, SALES!E:E, B124) -> 2
A125: BOTTLE | B125: PLASTIC EMPTY BOTTLE | C125: 6.25 | D125: PC/S | E125: =SUMIFS('STOCK IN TRANSFER'!G:G, 'STOCK IN TRANSFER'!E:E, B125, 'STOCK IN TRANSFER'!F:F, "STOCK IN") + SUMIFS('STOCK IN TRANSFER'!G:G, 'STOCK IN TRANSFER'!E:E, B125, 'STOCK IN TRANSFER'!F:F, "ADJUSTMENT (+)") - SUMIFS('STOCK IN TRANSFER'!G:G, 'STOCK IN TRANSFER'!E:E, B125, 'STOCK IN TRANSFER'!F:F, "ADJUSTMENT (-)") - SUMIFS('STOCK IN TRANSFER'!G:G, 'STOCK IN TRANSFER'!E:E, B125, 'STOCK IN TRANSFER'!F:F, "STOCK TRANSFER") - SUMIFS(SALES!H:H, SALES!E:E, B125) -> 0
A126: ROS-238 | B126: PISTACHIO ELASTOMERIC WATER FROOFING PAINT ROS-238 RAIN OR SHINE 4L | C126: 681.4 | D126: 4L | E126: =SUMIFS('STOCK IN TRANSFER'!G:G, 'STOCK IN TRANSFER'!E:E, B126, 'STOCK IN TRANSFER'!F:F, "STOCK IN") + SUMIFS('STOCK IN TRANSFER'!G:G, 'STOCK IN TRANSFER'!E:E, B126, 'STOCK IN TRANSFER'!F:F, "ADJUSTMENT (+)") - SUMIFS('STOCK IN TRANSFER'!G:G, 'STOCK IN TRANSFER'!E:E, B126, 'STOCK IN TRANSFER'!F:F, "ADJUSTMENT (-)") - SUMIFS('STOCK IN TRANSFER'!G:G, 'STOCK IN TRANSFER'!E:E, B126, 'STOCK IN TRANSFER'!F:F, "STOCK TRANSFER") - SUMIFS(SALES!H:H, SALES!E:E, B126) -> 1
A127: PINEPETHBLUE-4L | B127: PINACLE EPOXY ENAMEL THALO BLUE 4L | C127: 1160 | D127: GALON | E127: =SUMIFS('STOCK IN TRANSFER'!G:G, 'STOCK IN TRANSFER'!E:E, B127, 'STOCK IN TRANSFER'!F:F, "STOCK IN") + SUMIFS('STOCK IN TRANSFER'!G:G, 'STOCK IN TRANSFER'!E:E, B127, 'STOCK IN TRANSFER'!F:F, "ADJUSTMENT (+)") - SUMIFS('STOCK IN TRANSFER'!G:G, 'STOCK IN TRANSFER'!E:E, B127, 'STOCK IN TRANSFER'!F:F, "ADJUSTMENT (-)") - SUMIFS('STOCK IN TRANSFER'!G:G, 'STOCK IN TRANSFER'!E:E, B127, 'STOCK IN TRANSFER'!F:F, "STOCK TRANSFER") - SUMIFS(SALES!H:H, SALES!E:E, B127) -> 0
A128: PWTCO-9033 | B128: PHTHALO GREEN TINTING COLOR PWTCO-9033 1/4L PREMIUM WELCOAT | C128: 80.5933 | D128: 1/4L | E128: =SUMIFS('STOCK IN TRANSFER'!G:G, 'STOCK IN TRANSFER'!E:E, B128, 'STOCK IN TRANSFER'!F:F, "STOCK IN") + SUMIFS('STOCK IN TRANSFER'!G:G, 'STOCK IN TRANSFER'!E:E, B128, 'STOCK IN TRANSFER'!F:F, "ADJUSTMENT (+)") - SUMIFS('STOCK IN TRANSFER'!G:G, 'STOCK IN TRANSFER'!E:E, B128, 'STOCK IN TRANSFER'!F:F, "ADJUSTMENT (-)") - SUMIFS('STOCK IN TRANSFER'!G:G, 'STOCK IN TRANSFER'!E:E, B128, 'STOCK IN TRANSFER'!F:F, "STOCK TRANSFER") - SUMIFS(SALES!H:H, SALES!E:E, B128) -> 0
...

Sheet SALES
A1: DATE | B1: INVOICE NO. | C1: CUSTOMER'S NAME | D1: ITEM CODE | E1: DESCRIPTION | F1: COLOR CODE | G1: PAYMENT TYPE | H1: QTY | I1: UNIT | J1: UNIT PRICE | K1: TOTAL AMOUNT | L1: REMARKS
A2: 46113 | B2: SI-001253 | C2: RB CONSTRUCTION SUPPLY | D2: EXTREMEMIX-1L | E2: {=IF(D2="", "", XLOOKUP(D2, 'MASTER ITEM LIST'!A:A, 'MASTER ITEM LIST'!B:B, ""))} -> EXTREME QDU MIXING 1L | F2: EXTREME YELLOW | G2: CASH | H2: 3 | I2: {=IFERROR(XLOOKUP(D2,'MASTER ITEM LIST'!A:A,'MASTER ITEM LIST'!D:D), "")} -> LITER | J2: 750 | K2: =IF(H2="", "", H2*J2) -> 2250 | L2: PAID
A3: 46113 | B3: SI-001253 | C3: RB CONSTRUCTION SUPPLY | D3: PGJB-4L | E3: {=IF(D3="", "", XLOOKUP(D3, 'MASTER ITEM LIST'!A:A, 'MASTER ITEM LIST'!B:B, ""))} -> POLYGLOSS PU JET BLACK 4L | F3: REPACK | G3: CASH | H3: 0.125 | I3: {=IFERROR(XLOOKUP(D3,'MASTER ITEM LIST'!A:A,'MASTER ITEM LIST'!D:D), "")} -> GALON | J3: 3200 | K3: =IF(H3="", "", H3*J3) -> 400 | L3: PAID
A4: 46113 | B4: SI-001253 | C4: RB CONSTRUCTION SUPPLY | D4: NAX108 | E4: {=IF(D4="", "", XLOOKUP(D4, 'MASTER ITEM LIST'!A:A, 'MASTER ITEM LIST'!B:B, ""))} -> NAX 108 CERAMIC 2K CLEAR WITH HARDENER 1L | G4: CASH | H4: 3 | I4: {=IFERROR(XLOOKUP(D4,'MASTER ITEM LIST'!A:A,'MASTER ITEM LIST'!D:D), "")} -> LITER | J4: 700 | K4: =IF(H4="", "", H4*J4) -> 2100 | L4: PAID
A5: 46113 | B5: SI-001253 | C5: RB CONSTRUCTION SUPPLY | D5: DOITH-4L | E5: {=IF(D5="", "", XLOOKUP(D5, 'MASTER ITEM LIST'!A:A, 'MASTER ITEM LIST'!B:B, ""))} -> DO IT URETHANE THINNER 4L | G5: CASH | H5: 1.5 | I5: {=IFERROR(XLOOKUP(D5,'MASTER ITEM LIST'!A:A,'MASTER ITEM LIST'!D:D), "")} -> GAL/S | J5: 720 | K5: =IF(H5="", "", H5*J5) -> 1080 | L5: PAID
A6: 46113 | B6: SI-001253 | C6: RB CONSTRUCTION SUPPLY | D6: MSC | E6: {=IF(D6="", "", XLOOKUP(D6, 'MASTER ITEM LIST'!A:A, 'MASTER ITEM LIST'!B:B, ""))} -> OLD NEWS | G6: CASH | H6: 1 | I6: {=IFERROR(XLOOKUP(D6,'MASTER ITEM LIST'!A:A,'MASTER ITEM LIST'!D:D), "")} -> KG | J6: 100 | K6: =IF(H6="", "", H6*J6) -> 100 | L6: PAID
A7: 46113 | B7: SI-001252 | C7: JCK | D7: NXU1965-4L | E7: {=IF(D7="", "", XLOOKUP(D7, 'MASTER ITEM LIST'!A:A, 'MASTER ITEM LIST'!B:B, ""))} -> NIPPON EXTREME QDU BLACK 4L | F7: REPACK | G7: CASH | H7: 0.125 | I7: {=IFERROR(XLOOKUP(D7,'MASTER ITEM LIST'!A:A,'MASTER ITEM LIST'!D:D), "")} -> GAL | J7: 2800 | K7: =IF(H7="", "", H7*J7) -> 350 | L7: PAID
A8: 46113 | B8: SI-001252 | C8: JCK | D8: CRO-MT1/2 | E8: {=IF(D8="", "", XLOOKUP(D8, 'MASTER ITEM LIST'!A:A, 'MASTER ITEM LIST'!B:B, ""))} -> CROCO MASKING TAPE 1/2 12MM (1X96) | G8: CASH | H8: 3 | I8: {=IFERROR(XLOOKUP(D8,'MASTER ITEM LIST'!A:A,'MASTER ITEM LIST'!D:D), "")} -> PC/S | J8: 25 | K8: =IF(H8="", "", H8*J8) -> 75 | L8: PAID
A9: 46114 | B9: SI-001255 | C9: JEK | D9: NAX108 | E9: {=IF(D9="", "", XLOOKUP(D9, 'MASTER ITEM LIST'!A:A, 'MASTER ITEM LIST'!B:B, ""))} -> NAX 108 CERAMIC 2K CLEAR WITH HARDENER 1L | F9: REPACK | G9: CASH | H9: 0.5 | I9: {=IFERROR(XLOOKUP(D9,'MASTER ITEM LIST'!A:A,'MASTER ITEM LIST'!D:D), "")} -> LITER | J9: 740 | K9: =IF(H9="", "", H9*J9) -> 370 | L9: PAID
A10: 46114 | B10: SI-001254 | C10: BUKIDNON AUTOCARS | D10: NAT990-4L | E10: {=IF(D10="", "", XLOOKUP(D10, 'MASTER ITEM LIST'!A:A, 'MASTER ITEM LIST'!B:B, ""))} -> NAX NAT-990 TTC BLACK 4L | F10: REPACK | G10: CASH | H10: 0.5 | I10: {=IFERROR(XLOOKUP(D10,'MASTER ITEM LIST'!A:A,'MASTER ITEM LIST'!D:D), "")} -> GAL | J10: 4800 | K10: =IF(H10="", "", H10*J10) -> 2400 | L10: PAID
A11: 46118 | B11: SI-001256 | C11: WINDILL | D11: B1490-1L | E11: {=IF(D11="", "", XLOOKUP(D11, 'MASTER ITEM LIST'!A:A, 'MASTER ITEM LIST'!B:B, ""))} -> BOYSEN LTC LAMP BLACK 1L | G11: CASH | H11: 4 | I11: {=IFERROR(XLOOKUP(D11,'MASTER ITEM LIST'!A:A,'MASTER ITEM LIST'!D:D), "")} -> LITER | J11: 240 | K11: =IF(H11="", "", H11*J11) -> 960 | L11: PAID
A12: 46118 | B12: SI-001256 | C12: WINDILL | D12: RSW-4L | E12: {=IF(D12="", "", XLOOKUP(D12, 'MASTER ITEM LIST'!A:A, 'MASTER ITEM LIST'!B:B, ""))} -> RAIN OR SHINE WHITE 4L | G12: CASH | H12: 1 | I12: {=IFERROR(XLOOKUP(D12,'MASTER ITEM LIST'!A:A,'MASTER ITEM LIST'!D:D), "")} -> GALON | J12: 880 | K12: =IF(H12="", "", H12*J12) -> 880 | L12: PAID
A13: 46118 | B13: SI-001256 | C13: WINDILL | D13: 2B-#4 | E13: {=IF(D13="", "", XLOOKUP(D13, 'MASTER ITEM LIST'!A:A, 'MASTER ITEM LIST'!B:B, ""))} -> 2B PAINT ROLLER #4 | G13: CASH | H13: 2 | I13: {=IFERROR(XLOOKUP(D13,'MASTER ITEM LIST'!A:A,'MASTER ITEM LIST'!D:D), "")} -> PC/S | J13: 65 | K13: =IF(H13="", "", H13*J13) -> 130 | L13: PAID
A14: 46118 | B14: SI-001256 | C14: WINDILL | D14: 2B-#7 | E14: {=IF(D14="", "", XLOOKUP(D14, 'MASTER ITEM LIST'!A:A, 'MASTER ITEM LIST'!B:B, ""))} -> 2B PAINT ROLLER #7 | G14: CASH | H14: 1 | I14: {=IFERROR(XLOOKUP(D14,'MASTER ITEM LIST'!A:A,'MASTER ITEM LIST'!D:D), "")} -> PC/S | J14: 90 | K14: =IF(H14="", "", H14*J14) -> 90 | L14: PAID
A15: 46118 | B15: SI-001256 | C15: WINDILL | D15: EA120 | E15: {=IF(D15="", "", XLOOKUP(D15, 'MASTER ITEM LIST'!A:A, 'MASTER ITEM LIST'!B:B, ""))} -> EAGLE SANDPAPER #120 | G15: CASH | H15: 2 | I15: {=IFERROR(XLOOKUP(D15,'MASTER ITEM LIST'!A:A,'MASTER ITEM LIST'!D:D), "")} -> PC/S | J15: 25 | K15: =IF(H15="", "", H15*J15) -> 50 | L15: PAID
A16: 46118 | B16: SI-001256 | C16: WINDILL | D16: DPB-1 1/2 | E16: {=IF(D16="", "", XLOOKUP(D16, 'MASTER ITEM LIST'!A:A, 'MASTER ITEM LIST'!B:B, ""))} -> DRAGONFLY PAINT BRUSH #1 1/2 | G16: CASH | H16: 2 | I16: {=IFERROR(XLOOKUP(D16,'MASTER ITEM LIST'!A:A,'MASTER ITEM LIST'!D:D), "")} -> PC/S | J16: 40 | K16: =IF(H16="", "", H16*J16) -> 80 | L16: PAID
A17: 46118 | B17: SI-001256 | C17: WINDILL | D17: PUTTYKNI #4 | E17: {=IF(D17="", "", XLOOKUP(D17, 'MASTER ITEM LIST'!A:A, 'MASTER ITEM LIST'!B:B, ""))} -> JAPAN PUTTY KNIFE #4 | G17: CASH | H17: 2 | I17: {=IFERROR(XLOOKUP(D17,'MASTER ITEM LIST'!A:A,'MASTER ITEM LIST'!D:D), "")} -> PC/S | J17: 25 | K17: =IF(H17="", "", H17*J17) -> 50 | L17: PAID
A18: 46118 | B18: SI-001256 | C18: WINDILL | D18: EA120 | E18: {=IF(D18="", "", XLOOKUP(D18, 'MASTER ITEM LIST'!A:A, 'MASTER ITEM LIST'!B:B, ""))} -> EAGLE SANDPAPER #120 | G18: CASH | H18: 2 | I18: {=IFERROR(XLOOKUP(D18,'MASTER ITEM LIST'!A:A,'MASTER ITEM LIST'!D:D), "")} -> PC/S | J18: 25 | K18: =IF(H18="", "", H18*J18) -> 50 | L18: PAID
A19: 46118 | B19: SI-001256 | C19: WINDILL | D19: CRO-MT3/4 | E19: {=IF(D19="", "", XLOOKUP(D19, 'MASTER ITEM LIST'!A:A, 'MASTER ITEM LIST'!B:B, ""))} -> CROCO MASKING TAPE 3/4 18MM (1X64) | G19: CASH | H19: 2 | I19: {=IFERROR(XLOOKUP(D19,'MASTER ITEM LIST'!A:A,'MASTER ITEM LIST'!D:D), "")} -> PC/S | J19: 35 | K19: =IF(H19="", "", H19*J19) -> 70 | L19: PAID
A20: 46119 | B20: SI-001257 | C20: ALVIN | D20: NCGVARNISH-GAL | E20: {=IF(D20="", "", XLOOKUP(D20, 'MASTER ITEM LIST'!A:A, 'MASTER ITEM LIST'!B:B, ""))} -> NIPPON CLEAR GLOSS VARNISH GAL | G20: CASH | H20: 1 | I20: {=IFERROR(XLOOKUP(D20,'MASTER ITEM LIST'!A:A,'MASTER ITEM LIST'!D:D), "")} -> GAL | J20: 1800 | K20: =IF(H20="", "", H20*J20) -> 1800 | L20: PAID
A21: 46120 | B21: SI-001261 | C21: JUNDAPS | D21: CRO-MT3/4 | E21: {=IF(D21="", "", XLOOKUP(D21, 'MASTER ITEM LIST'!A:A, 'MASTER ITEM LIST'!B:B, ""))} -> CROCO MASKING TAPE 3/4 18MM (1X64) | G21: CASH | H21: 2 | I21: {=IFERROR(XLOOKUP(D21,'MASTER ITEM LIST'!A:A,'MASTER ITEM LIST'!D:D), "")} -> PC/S | J21: 35 | K21: =IF(H21="", "", H21*J21) -> 70 | L21: PAID
A22: 46120 | B22: SI-001261 | C22: JUNDAPS | D22: TOBF-4L | E22: {=IF(D22="", "", XLOOKUP(D22, 'MASTER ITEM LIST'!A:A, 'MASTER ITEM LIST'!B:B, ""))} -> TIMEOUT BODY FILLER WITH HARDENER 4L | G22: CASH | H22: 1 | I22: {=IFERROR(XLOOKUP(D22,'MASTER ITEM LIST'!A:A,'MASTER ITEM LIST'!D:D), "")} -> GAL | J22: 710 | K22: =IF(H22="", "", H22*J22) -> 710 | L22: PAID
A23: 46120 | B23: SI-001261 | C23: JUNDAPS | D23: NAX141 | E23: {=IF(D23="", "", XLOOKUP(D23, 'MASTER ITEM LIST'!A:A, 'MASTER ITEM LIST'!B:B, ""))} -> NAX 141 NAX MAXIMA URETHANE FD CLEAR WITH HARDENER 1L | G23: CASH | H23: 4 | I23: {=IFERROR(XLOOKUP(D23,'MASTER ITEM LIST'!A:A,'MASTER ITEM LIST'!D:D), "")} -> LITER | J23: 580 | K23: =IF(H23="", "", H23*J23) -> 2320 | L23: PAID
A24: 46120 | B24: SI-001261 | C24: JUNDAPS | D24: NAXQDUMIX-1L | E24: {=IF(D24="", "", XLOOKUP(D24, 'MASTER ITEM LIST'!A:A, 'MASTER ITEM LIST'!B:B, ""))} -> NAX QDU MIX 1L | F24: QDU BLUE | G24: CASH | H24: 2 | I24: {=IFERROR(XLOOKUP(D24,'MASTER ITEM LIST'!A:A,'MASTER ITEM LIST'!D:D), "")} -> LITER | J24: 800 | K24: =IF(H24="", "", H24*J24) -> 1600 | L24: PAID
A25: 46120 | B25: SI-001261 | C25: JUNDAPS | D25: NAXQDUMIX-1L | E25: {=IF(D25="", "", XLOOKUP(D25, 'MASTER ITEM LIST'!A:A, 'MASTER ITEM LIST'!B:B, ""))} -> NAX QDU MIX 1L | F25: QDU YELLOW | G25: CASH | H25: 1 | I25: {=IFERROR(XLOOKUP(D25,'MASTER ITEM LIST'!A:A,'MASTER ITEM LIST'!D:D), "")} -> LITER | J25: 700 | K25: =IF(H25="", "", H25*J25) -> 700 | L25: PAID
A26: 46120 | B26: SI-001261 | C26: JUNDAPS | D26: NAXQDUMIX-1L | E26: {=IF(D26="", "", XLOOKUP(D26, 'MASTER ITEM LIST'!A:A, 'MASTER ITEM LIST'!B:B, ""))} -> NAX QDU MIX 1L | F26: QDU GREEN | G26: CASH | H26: 0.25 | I26: {=IFERROR(XLOOKUP(D26,'MASTER ITEM LIST'!A:A,'MASTER ITEM LIST'!D:D), "")} -> LITER | J26: 800 | K26: =IF(H26="", "", H26*J26) -> 200 | L26: PAID
A27: 46120 | B27: SI-001260 | C27: JUNDAPS | D27: EA100 | E27: {=IF(D27="", "", XLOOKUP(D27, 'MASTER ITEM LIST'!A:A, 'MASTER ITEM LIST'!B:B, ""))} -> SAND PAPER #100 | G27: CASH | H27: 3 | I27: {=IFERROR(XLOOKUP(D27,'MASTER ITEM LIST'!A:A,'MASTER ITEM LIST'!D:D), "")} -> PC/S | J27: 40 | K27: =IF(H27="", "", H27*J27) -> 120 | L27: PAID
A28: 46120 | B28: SI-001260 | C28: JUNDAPS | D28: EA120 | E28: {=IF(D28="", "", XLOOKUP(D28, 'MASTER ITEM LIST'!A:A, 'MASTER ITEM LIST'!B:B, ""))} -> EAGLE SANDPAPER #120 | G28: CASH | H28: 3 | I28: {=IFERROR(XLOOKUP(D28,'MASTER ITEM LIST'!A:A,'MASTER ITEM LIST'!D:D), "")} -> PC/S | J28: 25 | K28: =IF(H28="", "", H28*J28) -> 75 | L28: PAID
A29: 46120 | B29: SI-001260 | C29: JUNDAPS | D29: ea1500 | E29: {=IF(D29="", "", XLOOKUP(D29, 'MASTER ITEM LIST'!A:A, 'MASTER ITEM LIST'!B:B, ""))} -> EAGLE SANDPAPER #1500 | G29: CASH | H29: 1 | I29: {=IFERROR(XLOOKUP(D29,'MASTER ITEM LIST'!A:A,'MASTER ITEM LIST'!D:D), "")} -> PC/S | J29: 35 | K29: =IF(H29="", "", H29*J29) -> 35 | L29: PAID
A30: 46120 | B30: SI-001260 | C30: JUNDAPS | D30: EA2000 | E30: {=IF(D30="", "", XLOOKUP(D30, 'MASTER ITEM LIST'!A:A, 'MASTER ITEM LIST'!B:B, ""))} -> EAGLE SANDPAPER #2000 | G30: CASH | H30: 1 | I30: {=IFERROR(XLOOKUP(D30,'MASTER ITEM LIST'!A:A,'MASTER ITEM LIST'!D:D), "")} -> PC/S | J30: 35 | K30: =IF(H30="", "", H30*J30) -> 35 | L30: PAID
A31: 46120 | B31: SI-001260 | C31: JUNDAPS | D31: MSC | E31: {=IF(D31="", "", XLOOKUP(D31, 'MASTER ITEM LIST'!A:A, 'MASTER ITEM LIST'!B:B, ""))} -> OLD NEWS | G31: CASH | H31: 1 | I31: {=IFERROR(XLOOKUP(D31,'MASTER ITEM LIST'!A:A,'MASTER ITEM LIST'!D:D), "")} -> KG | J31: 100 | K31: =IF(H31="", "", H31*J31) -> 100 | L31: PAID
A32: 46120 | B32: SI-001260 | C32: JUNDAPS | D32: DOITH-4L | E32: {=IF(D32="", "", XLOOKUP(D32, 'MASTER ITEM LIST'!A:A, 'MASTER ITEM LIST'!B:B, ""))} -> DO IT URETHANE THINNER 4L | G32: CASH | H32: 2 | I32: {=IFERROR(XLOOKUP(D32,'MASTER ITEM LIST'!A:A,'MASTER ITEM LIST'!D:D), "")} -> GAL/S | J32: 710 | K32: =IF(H32="", "", H32*J32) -> 1420 | L32: PAID
A33: 46120 | B33: SI-001258 | C33: ELECTROKIM | D33: NP9200 | E33: {=IF(D33="", "", XLOOKUP(D33, 'MASTER ITEM LIST'!A:A, 'MASTER ITEM LIST'!B:B, ""))} -> NAX PREMILA NP9200 2K CLEAR WITH HARDENER 1L | G33: CASH | H33: 1 | I33: {=IFERROR(XLOOKUP(D33,'MASTER ITEM LIST'!A:A,'MASTER ITEM LIST'!D:D), "")} -> LITER | J33: 1350 | K33: =IF(H33="", "", H33*J33) -> 1350 | L33: PAID
A34: 46120 | B34: SI-001259 | C34: APARESE | D34: PREMILAMIX-1L | E34: {=IF(D34="", "", XLOOKUP(D34, 'MASTER ITEM LIST'!A:A, 'MASTER ITEM LIST'!B:B, ""))} -> PREMILA MIXING 1L | F34: CODE: U25 SILVER | G34: CASH | H34: 0.2 | I34: {=IFERROR(XLOOKUP(D34,'MASTER ITEM LIST'!A:A,'MASTER ITEM LIST'!D:D), "")} -> LITER | J34: 2400 | K34: =IF(H34="", "", H34*J34) -> 480 | L34: PAID
A35: 46121 | B35: SI-001262 | C35: BUKIDNON AUTOCARS | D35: NAX108 | E35: {=IF(D35="", "", XLOOKUP(D35, 'MASTER ITEM LIST'!A:A, 'MASTER ITEM LIST'!B:B, ""))} -> NAX 108 CERAMIC 2K CLEAR WITH HARDENER 1L | G35: CASH | H35: 12 | I35: {=IFERROR(XLOOKUP(D35,'MASTER ITEM LIST'!A:A,'MASTER ITEM LIST'!D:D), "")} -> LITER | J35: 680 | K35: =IF(H35="", "", H35*J35) -> 8160 | L35: PAID
A36: 46121 | B36: SI-001262 | C36: BUKIDNON AUTOCARS | D36: PRI3634 | E36: {=IF(D36="", "", XLOOKUP(D36, 'MASTER ITEM LIST'!A:A, 'MASTER ITEM LIST'!B:B, ""))} -> NAX ALPHA HB SPRAY FILLER GRAY WITH HARDENER 1L | G36: CASH | H36: 12 | I36: {=IFERROR(XLOOKUP(D36,'MASTER ITEM LIST'!A:A,'MASTER ITEM LIST'!D:D), "")} -> LITER | J36: 580 | K36: =IF(H36="", "", H36*J36) -> 6960 | L36: PAID
A37: 46121 | B37: SI-001262 | C37: BUKIDNON AUTOCARS | D37: PGJB-4L | E37: {=IF(D37="", "", XLOOKUP(D37, 'MASTER ITEM LIST'!A:A, 'MASTER ITEM LIST'!B:B, ""))} -> POLYGLOSS PU JET BLACK 4L | G37: CASH | H37: 1 | I37: {=IFERROR(XLOOKUP(D37,'MASTER ITEM LIST'!A:A,'MASTER ITEM LIST'!D:D), "")} -> GALON | J37: 2600 | K37: =IF(H37="", "", H37*J37) -> 2600 | L37: PAID
A38: 46121 | B38: SI-001262 | C38: BUKIDNON AUTOCARS | D38: PGW-4L | E38: {=IF(D38="", "", XLOOKUP(D38, 'MASTER ITEM LIST'!A:A, 'MASTER ITEM LIST'!B:B, ""))} -> POLYGLOSS PU WHITE 4L | G38: CASH | H38: 1 | I38: {=IFERROR(XLOOKUP(D38,'MASTER ITEM LIST'!A:A,'MASTER ITEM LIST'!D:D), "")} -> GALON | J38: 2400 | K38: =IF(H38="", "", H38*J38) -> 2400 | L38: PAID
A39: 46121 | B39: SI-001262 | C39: BUKIDNON AUTOCARS | D39: DOMBF-4L | E39: {=IF(D39="", "", XLOOKUP(D39, 'MASTER ITEM LIST'!A:A, 'MASTER ITEM LIST'!B:B, ""))} -> DOMINO BODY FILTER WITH HARDENER 4L | G39: CASH | H39: 3 | I39: {=IFERROR(XLOOKUP(D39,'MASTER ITEM LIST'!A:A,'MASTER ITEM LIST'!D:D), "")} -> GAL | J39: 615 | K39: =IF(H39="", "", H39*J39) -> 1845 | L39: PAID
A40: 46121 | B40: SI-001263 | C40: BUKIDNON AUTOCARS | D40: POLYGTHIN-4L | E40: {=IF(D40="", "", XLOOKUP(D40, 'MASTER ITEM LIST'!A:A, 'MASTER ITEM LIST'!B:B, ""))} -> POLYGLOSS URETHANE THINNER 4L | G40: CASH | H40: 6 | I40: {=IFERROR(XLOOKUP(D40,'MASTER ITEM LIST'!A:A,'MASTER ITEM LIST'!D:D), "")} -> GALON | J40: 800 | K40: =IF(H40="", "", H40*J40) -> 4800 | L40: PAID
...

Sheet STOCK IN  TRANSFER
A1: DATE | B1: REF. NO. | C1: SUPPLIER | D1: ITEM CODE | E1: DESCRIPTION | F1: TYPE | G1: QTY | H1: UNIT | I1: UNIT PRICE | J1: TOTAL AMOUNT
A2: 25/04/0226 | B2: CSI-03664 | C2: APC DISTRIBUTION - VALENCIA | D2: 2B-PB-2 | E2: {=IF(D2="", "", XLOOKUP(D2, 'MASTER ITEM LIST'!A:A, 'MASTER ITEM LIST'!B:B, ""))} -> 2B PAINT BRUSH #2 | F2: STOCK IN | G2: 12 | H2: {=IFERROR(XLOOKUP(D2,'MASTER ITEM LIST'!A:A,'MASTER ITEM LIST'!D:D), "")} -> PC/S | I2: 30.5 | J2: =IF(G2="", "",G2*I2) -> 366
A3: 46112 | C3: INVENTORY - MARCH 31, 2026 | D3: MT904 | E3: {=IF(D3="", "", XLOOKUP(D3, 'MASTER ITEM LIST'!A:A, 'MASTER ITEM LIST'!B:B, ""))} -> NAX PREMILA MT904 SHADOWN GREEN 1L | F3: STOCK IN | G3: 3 | H3: {=IFERROR(XLOOKUP(D3,'MASTER ITEM LIST'!A:A,'MASTER ITEM LIST'!D:D), "")} -> LTR/S | I3: 1593 | J3: =IF(G3="", "",G3*I3) -> 4779
A4: 46112 | C4: INVENTORY - MARCH 31, 2026 | D4: MT903 | E4: {=IF(D4="", "", XLOOKUP(D4, 'MASTER ITEM LIST'!A:A, 'MASTER ITEM LIST'!B:B, ""))} -> NAX PREMILA MT903 SUN GREEN 1L | F4: STOCK IN | G4: 3 | H4: {=IFERROR(XLOOKUP(D4,'MASTER ITEM LIST'!A:A,'MASTER ITEM LIST'!D:D), "")} -> LTR/S | I4: 1561 | J4: =IF(G4="", "",G4*I4) -> 4683
A5: 46112 | C5: INVENTORY - MARCH 31, 2026 | D5: MT902 | E5: {=IF(D5="", "", XLOOKUP(D5, 'MASTER ITEM LIST'!A:A, 'MASTER ITEM LIST'!B:B, ""))} -> NAX PREMILA MT902 GRASS GREEN 1L | F5: STOCK IN | G5: 3 | H5: {=IFERROR(XLOOKUP(D5,'MASTER ITEM LIST'!A:A,'MASTER ITEM LIST'!D:D), "")} -> LTR/S | I5: 1593 | J5: =IF(G5="", "",G5*I5) -> 4779
A6: 46112 | C6: INVENTORY - MARCH 31, 2026 | D6: MT807 | E6: {=IF(D6="", "", XLOOKUP(D6, 'MASTER ITEM LIST'!A:A, 'MASTER ITEM LIST'!B:B, ""))} -> NAX PREMILA MT807 VACANCE BLUE 1L | F6: STOCK IN | G6: 3 | H6: {=IFERROR(XLOOKUP(D6,'MASTER ITEM LIST'!A:A,'MASTER ITEM LIST'!D:D), "")} -> LTR/S | I6: 1593 | J6: =IF(G6="", "",G6*I6) -> 4779
A7: 46112 | C7: INVENTORY - MARCH 31, 2026 | D7: MT806 | E7: {=IF(D7="", "", XLOOKUP(D7, 'MASTER ITEM LIST'!A:A, 'MASTER ITEM LIST'!B:B, ""))} -> NAX PREMILA MT806 HERMES BLUE 1L | F7: STOCK IN | G7: 2 | H7: {=IFERROR(XLOOKUP(D7,'MASTER ITEM LIST'!A:A,'MASTER ITEM LIST'!D:D), "")} -> LTR/S | I7: 1593 | J7: =IF(G7="", "",G7*I7) -> 3186
A8: 46112 | C8: INVENTORY - MARCH 31, 2026 | D8: MT805 | E8: {=IF(D8="", "", XLOOKUP(D8, 'MASTER ITEM LIST'!A:A, 'MASTER ITEM LIST'!B:B, ""))} -> NAX PREMILA MT805 CUSTOM BLUE 1L | F8: STOCK IN | G8: 1 | H8: {=IFERROR(XLOOKUP(D8,'MASTER ITEM LIST'!A:A,'MASTER ITEM LIST'!D:D), "")} -> LTR/S | I8: 1593 | J8: =IF(G8="", "",G8*I8) -> 1593
A9: 46112 | C9: INVENTORY - MARCH 31, 2026 | D9: MT804 | E9: {=IF(D9="", "", XLOOKUP(D9, 'MASTER ITEM LIST'!A:A, 'MASTER ITEM LIST'!B:B, ""))} -> NAX PREMILA MT804 ORIENT BLUE 1L | F9: STOCK IN | G9: 1 | H9: {=IFERROR(XLOOKUP(D9,'MASTER ITEM LIST'!A:A,'MASTER ITEM LIST'!D:D), "")} -> LTR/S | I9: 1593 | J9: =IF(G9="", "",G9*I9) -> 1593
A10: 46112 | C10: INVENTORY - MARCH 31, 2026 | D10: MT803 | E10: {=IF(D10="", "", XLOOKUP(D10, 'MASTER ITEM LIST'!A:A, 'MASTER ITEM LIST'!B:B, ""))} -> NAX PREMILA MT803 FRESH BLUE 1L | F10: STOCK IN | G10: 2 | H10: {=IFERROR(XLOOKUP(D10,'MASTER ITEM LIST'!A:A,'MASTER ITEM LIST'!D:D), "")} -> LTR/S | I10: 1593 | J10: =IF(G10="", "",G10*I10) -> 3186
A11: 46112 | C11: INVENTORY - MARCH 31, 2026 | D11: MT801 | E11: {=IF(D11="", "", XLOOKUP(D11, 'MASTER ITEM LIST'!A:A, 'MASTER ITEM LIST'!B:B, ""))} -> NAX PREMILA MT801 CYANINE BLUE 1L | F11: STOCK IN | G11: 3 | H11: {=IFERROR(XLOOKUP(D11,'MASTER ITEM LIST'!A:A,'MASTER ITEM LIST'!D:D), "")} -> LTR/S | I11: 1593 | J11: =IF(G11="", "",G11*I11) -> 4779
A12: 46112 | C12: INVENTORY - MARCH 31, 2026 | D12: MT705 | E12: {=IF(D12="", "", XLOOKUP(D12, 'MASTER ITEM LIST'!A:A, 'MASTER ITEM LIST'!B:B, ""))} -> NAX PREMILA MT705 FLORA VIOLET 1L | F12: STOCK IN | G12: 4 | H12: {=IFERROR(XLOOKUP(D12,'MASTER ITEM LIST'!A:A,'MASTER ITEM LIST'!D:D), "")} -> LTR/S | I12: 1896 | J12: =IF(G12="", "",G12*I12) -> 7584
A13: 46112 | C13: INVENTORY - MARCH 31, 2026 | D13: MT704 | E13: {=IF(D13="", "", XLOOKUP(D13, 'MASTER ITEM LIST'!A:A, 'MASTER ITEM LIST'!B:B, ""))} -> NAX PREMILA MT704 FINE VIOLET 1L | F13: STOCK IN | G13: 3 | H13: {=IFERROR(XLOOKUP(D13,'MASTER ITEM LIST'!A:A,'MASTER ITEM LIST'!D:D), "")} -> LTR/S | I13: 1593 | J13: =IF(G13="", "",G13*I13) -> 4779
A14: 46112 | C14: INVENTORY - MARCH 31, 2026 | D14: MT607 | E14: {=IF(D14="", "", XLOOKUP(D14, 'MASTER ITEM LIST'!A:A, 'MASTER ITEM LIST'!B:B, ""))} -> NAX PREMILA MT607 AUTUMN RED 1L | F14: STOCK IN | G14: 1 | H14: {=IFERROR(XLOOKUP(D14,'MASTER ITEM LIST'!A:A,'MASTER ITEM LIST'!D:D), "")} -> LTR/S | I14: 2048 | J14: =IF(G14="", "",G14*I14) -> 2048
... A341: 46127 | C341: TRANSFER TO MIXING AREA | D341: PNB100 | E341: {=IF(D341="", "", XLOOKUP(D341, 'MASTER ITEM LIST'!A:A, 'MASTER ITEM LIST'!B:B, ""))} -> NAX PREMILA NB100 B/C BINDER 4L | F341: ADJUSTMENT (-) | G341: 1 | H341: {=IFERROR(XLOOKUP(D341,'MASTER ITEM LIST'!A:A,'MASTER ITEM LIST'!D:D), "")} -> GAL | I341: 2100 | J341: =IF(G341="", "",G341*I341) -> 2100
A342: 46128 | B342: CSI-03653 | C342: APC DISTRIBUTION - VALENCIA | D342: DOMBF-1L | E342: {=IF(D342="", "", XLOOKUP(D342, 'MASTER ITEM LIST'!A:A, 'MASTER ITEM LIST'!B:B, ""))} -> DOMINO BODY FILTER WITH HARDENER 1L | F342: STOCK IN | G342: 12 | H342: {=IFERROR(XLOOKUP(D342,'MASTER ITEM LIST'!A:A,'MASTER ITEM LIST'!D:D), "")} -> LITER | I342: 150 | J342: =IF(G342="", "",G342*I342) -> 1800
A343: 46128 | B343: CSI-03653 | C343: APC DISTRIBUTION - VALENCIA | D343: CRO-MT3/4 | E343: {=IF(D343="", "", XLOOKUP(D343, 'MASTER ITEM LIST'!A:A, 'MASTER ITEM LIST'!B:B, ""))} -> CROCO MASKING TAPE 3/4 18MM (1X64) | F343: STOCK IN | G343: 64 | H343: {=IFERROR(XLOOKUP(D343,'MASTER ITEM LIST'!A:A,'MASTER ITEM LIST'!D:D), "")} -> PC/S | I343: 23.59 | J343: =IF(G343="", "",G343*I343) -> 1509.76
A344: 46128 | B344: CSI-03653 | C344: APC DISTRIBUTION - VALENCIA | D344: GLAZERB-4L | E344: {=IF(D344="", "", XLOOKUP(D344, 'MASTER ITEM LIST'!A:A, 'MASTER ITEM LIST'!B:B, ""))} -> GLAZER AUTOMOTIVE ENAMEL BLACK 4L | F344: STOCK IN | G344: 1 | H344: {=IFERROR(XLOOKUP(D344,'MASTER ITEM LIST'!A:A,'MASTER ITEM LIST'!D:D), "")} -> GALON | I344: 855 | J344: =IF(G344="", "",G344*I344) -> 855
A345: 46128 | B345: CSI-03653 | C345: APC DISTRIBUTION - VALENCIA | D345: NXU4075-4L | E345: {=IF(D345="", "", XLOOKUP(D345, 'MASTER ITEM LIST'!A:A, 'MASTER ITEM LIST'!B:B, ""))} -> NIPPON EXTREME QDU WHITE 4L | F345: STOCK IN | G345: 3 | H345: {=IFERROR(XLOOKUP(D345,'MASTER ITEM LIST'!A:A,'MASTER ITEM LIST'!D:D), "")} -> GAL | I345: 1550 | J345: =IF(G345="", "",G345*I345) -> 4650
A346: 46128 | B346: CSI-03653 | C346: APC DISTRIBUTION - VALENCIA | D346: NXU7391-4L | E346: {=IF(D346="", "", XLOOKUP(D346, 'MASTER ITEM LIST'!A:A, 'MASTER ITEM LIST'!B:B, ""))} -> NIPPON EXTREME QDU SILVER 4L | F346: STOCK IN | G346: 1 | H346: {=IFERROR(XLOOKUP(D346,'MASTER ITEM LIST'!A:A,'MASTER ITEM LIST'!D:D), "")} -> GAL | I346: 1493 | J346: =IF(G346="", "",G346*I346) -> 1493
A347: 46128 | B347: CSI-03653 | C347: APC DISTRIBUTION - VALENCIA | D347: ROS-739 | E347: {=IF(D347="", "", XLOOKUP(D347, 'MASTER ITEM LIST'!A:A, 'MASTER ITEM LIST'!B:B, ""))} -> COCONUT ELASTOMERIC WATER FROOFING PAINT ROS-739 RAIN OR SHINE 4L | F347: STOCK IN | G347: 1 | H347: {=IFERROR(XLOOKUP(D347,'MASTER ITEM LIST'!A:A,'MASTER ITEM LIST'!D:D), "")} -> 4L | I347: 695 | J347: =IF(G347="", "",G347*I347) -> 695
A348: 46128 | B348: CSI-03653 | C348: APC DISTRIBUTION - VALENCIA | D348: PG888-4L | E348: {=IF(D348="", "", XLOOKUP(D348, 'MASTER ITEM LIST'!A:A, 'MASTER ITEM LIST'!B:B, ""))} -> POLYGLOSS PU 888 RED 4L | F348: STOCK IN | G348: 1 | H348: {=IFERROR(XLOOKUP(D348,'MASTER ITEM LIST'!A:A,'MASTER ITEM LIST'!D:D), "")} -> GALON | I348: 2448 | J348: =IF(G348="", "",G348*I348) -> 2448
A349: 46128 | B349: CSI-03653 | C349: APC DISTRIBUTION - VALENCIA | D349: PGW-4L | E349: {=IF(D349="", "", XLOOKUP(D349, 'MASTER ITEM LIST'!A:A, 'MASTER ITEM LIST'!B:B, ""))} -> POLYGLOSS PU WHITE 4L | F349: STOCK IN | G349: 2 | H349: {=IFERROR(XLOOKUP(D349,'MASTER ITEM LIST'!A:A,'MASTER ITEM LIST'!D:D), "")} -> GALON | I349: 1730 | J349: =IF(G349="", "",G349*I349) -> 3460
A350: 46128 | B350: CSI-03653 | C350: APC DISTRIBUTION - VALENCIA | D350: PGJB-4L | E350: {=IF(D350="", "", XLOOKUP(D350, 'MASTER ITEM LIST'!A:A, 'MASTER ITEM LIST'!B:B, ""))} -> POLYGLOSS PU JET BLACK 4L | F350: STOCK IN | G350: 1 | H350: {=IFERROR(XLOOKUP(D350,'MASTER ITEM LIST'!A:A,'MASTER ITEM LIST'!D:D), "")} -> GALON | I350: 1830 | J350: =IF(G350="", "",G350*I350) -> 1830
A351: 46128 | B351: CSI-03653 | C351: APC DISTRIBUTION - VALENCIA | D351: EA2000 | E351: {=IF(D351="", "", XLOOKUP(D351, 'MASTER ITEM LIST'!A:A, 'MASTER ITEM LIST'!B:B, ""))} -> EAGLE SANDPAPER #2000 | F351: STOCK IN | G351: 100 | H351: {=IFERROR(XLOOKUP(D351,'MASTER ITEM LIST'!A:A,'MASTER ITEM LIST'!D:D), "")} -> PC/S | I351: 28 | J351: =IF(G351="", "",G351*I351) -> 2800
A352: 46128 | B352: CSI-03654 | C352: APC DISTRIBUTION - VALENCIA | D352: NP9200 | E352: {=IF(D352="", "", XLOOKUP(D352, 'MASTER ITEM LIST'!A:A, 'MASTER ITEM LIST'!B:B, ""))} -> NAX PREMILA NP9200 2K CLEAR WITH HARDENER 1L | F352: STOCK IN | G352: 12 | H352: {=IFERROR(XLOOKUP(D352,'MASTER ITEM LIST'!A:A,'MASTER ITEM LIST'!D:D), "")} -> LITER | I352: 920 | J352: =IF(G352="", "",G352*I352) -> 11040
A353: 46128 | B353: CSI-03654 | C353: APC DISTRIBUTION - VALENCIA | D353: DOITH-4L | E353: {=IF(D353="", "", XLOOKUP(D353, 'MASTER ITEM LIST'!A:A, 'MASTER ITEM LIST'!B:B, ""))} -> DO IT URETHANE THINNER 4L | F353: STOCK IN | G353: 12 | H353: {=IFERROR(XLOOKUP(D353,'MASTER ITEM LIST'!A:A,'MASTER ITEM LIST'!D:D), "")} -> GAL/S | I353: 590 | J353: =IF(G353="", "",G353*I353) -> 7080
... A361: 46129 | B361: CSI-03656 | C361: APC DISTRIBUTION - VALENCIA | D361: POLYGTHIN-4L | E361: {=IF(D361="", "", XLOOKUP(D361, 'MASTER ITEM LIST'!A:A, 'MASTER ITEM LIST'!B:B, ""))} -> POLYGLOSS URETHANE THINNER 4L | F361: STOCK IN | G361: 6 | H361: {=IFERROR(XLOOKUP(D361,'MASTER ITEM LIST'!A:A,'MASTER ITEM LIST'!D:D), "")} -> GALON | I361: 650 | J361: =IF(G361="", "",G361*I361) -> 3900
A362: 46130 | C362: TRANSFER TO MIXING AREA | D362: NAT719-4L | E362: {=IF(D362="", "", XLOOKUP(D362, 'MASTER ITEM LIST'!A:A, 'MASTER ITEM LIST'!B:B, ""))} -> NAX NAT-719 TTC COARSE SILVER 4L | F362: ADJUSTMENT (-) | G362: 1 | H362: {=IFERROR(XLOOKUP(D362,'MASTER ITEM LIST'!A:A,'MASTER ITEM LIST'!D:D), "")} -> GAL | I362: 2325 | J362: =IF(G362="", "",G362*I362) -> 2325
A363: 46130 | C363: TRANSFER TO MIXING AREA | D363: NAT192 | E363: {=IF(D363="", "", XLOOKUP(D363, 'MASTER ITEM LIST'!A:A, 'MASTER ITEM LIST'!B:B, ""))} -> NAX NAT-192 TTC BRIGHT RED 1L | F363: ADJUSTMENT (-) | G363: 1 | H363: {=IFERROR(XLOOKUP(D363,'MASTER ITEM LIST'!A:A,'MASTER ITEM LIST'!D:D), "")} -> LITER | I363: 540 | J363: =IF(G363="", "",G363*I363) -> 540
A364: 46130 | C364: TRANSFER TO MIXING AREA | D364: NAT320 | E364: {=IF(D364="", "", XLOOKUP(D364, 'MASTER ITEM LIST'!A:A, 'MASTER ITEM LIST'!B:B, ""))} -> NAX NAT-320 TTC GOLD YELLOW 1L | F364: ADJUSTMENT (-) | G364: 1 | H364: {=IFERROR(XLOOKUP(D364,'MASTER ITEM LIST'!A:A,'MASTER ITEM LIST'!D:D), "")} -> LITER | I364: 425 | J364: =IF(G364="", "",G364*I364) -> 425
A365: 46130 | C365: TRANSFER TO MIXING AREA | D365: CRO-MT1 | E365: {=IF(D365="", "", XLOOKUP(D365, 'MASTER ITEM LIST'!A:A, 'MASTER ITEM LIST'!B:B, ""))} -> CROCO MASKING TAPE #1 | F365: ADJUSTMENT (-) | G365: 1 | H365: {=IFERROR(XLOOKUP(D365,'MASTER ITEM LIST'!A:A,'MASTER ITEM LIST'!D:D), "")} -> PCS | I365: 32 | J365: =IF(G365="", "",G365*I365) -> 32
A366: 46132 | C366: TRANSFER TO MIXING AREA | D366: WCPOD | E366: {=IF(D366="", "", XLOOKUP(D366, 'MASTER ITEM LIST'!A:A, 'MASTER ITEM LIST'!B:B, ""))} -> WASTE COTTON POD | F366: ADJUSTMENT (-) | G366: 1 | H366: {=IFERROR(XLOOKUP(D366,'MASTER ITEM LIST'!A:A,'MASTER ITEM LIST'!D:D), "")} -> KL | I366: 70 | J366: =IF(G366="", "",G366*I366) -> 70
A367: 46132 | C367: TRANSFER TO MIXING AREA | D367: PNB100 | E367: {=IF(D367="", "", XLOOKUP(D367, 'MASTER ITEM LIST'!A:A, 'MASTER ITEM LIST'!B:B, ""))} -> NAX PREMILA NB100 B/C BINDER 4L | F367: ADJUSTMENT (-) | G367: 1 | H367: {=IFERROR(XLOOKUP(D367,'MASTER ITEM LIST'!A:A,'MASTER ITEM LIST'!D:D), "")} -> GAL | I367: 2100 | J367: =IF(G367="", "",G367*I367) -> 2100
A368: 46133 | C368: TRANSFER TO MIXING AREA | D368: DV400-WHITE-4L | E368: {=IF(D368="", "", XLOOKUP(D368, 'MASTER ITEM LIST'!A:A, 'MASTER ITEM LIST'!B:B, ""))} -> DAVIES QDE WHITE 4L | F368: ADJUSTMENT (-) | G368: 1 | H368: {=IFERROR(XLOOKUP(D368,'MASTER ITEM LIST'!A:A,'MASTER ITEM LIST'!D:D), "")} -> GALON | I368: 820 | J368: =IF(G368="", "",G368*I368) -> 820
A369: 46134 | C369: TRANSFER TO MIXING AREA | D369: NAX10100 | E369: {=IF(D369="", "", XLOOKUP(D369, 'MASTER ITEM LIST'!A:A, 'MASTER ITEM LIST'!B:B, ""))} -> NAX NAT-10100 NH-585 PEARL WHITE MICA 1L | F369: ADJUSTMENT (-) | G369: 1 | H369: {=IFERROR(XLOOKUP(D369,'MASTER ITEM LIST'!A:A,'MASTER ITEM LIST'!D:D), "")} -> LITER | I369: 675 | J369: =IF(G369="", "",G369*I369) -> 675
A370: 46134 | C370: TRANSFER TO MIXING AREA | D370: NXU1965-4L | E370: {=IF(D370="", "", XLOOKUP(D370, 'MASTER ITEM LIST'!A:A, 'MASTER ITEM LIST'!B:B, ""))} -> NIPPON EXTREME QDU BLACK 4L | F370: ADJUSTMENT (-) | G370: 1 | H370: {=IFERROR(XLOOKUP(D370,'MASTER ITEM LIST'!A:A,'MASTER ITEM LIST'!D:D), "")} -> GAL | I370: 1485 | J370: =IF(G370="", "",G370*I370) -> 1485
A371: 46135 | C371: TRANSFER TO MIXING AREA | D371: PNB100 | E371: {=IF(D371="", "", XLOOKUP(D371, 'MASTER ITEM LIST'!A:A, 'MASTER ITEM LIST'!B:B, ""))} -> NAX PREMILA NB100 B/C BINDER 4L | F371: ADJUSTMENT (-) | G371: 1 | H371: {=IFERROR(XLOOKUP(D371,'MASTER ITEM LIST'!A:A,'MASTER ITEM LIST'!D:D), "")} -> GAL | I371: 2100 | J371: =IF(G371="", "",G371*I371) -> 2100
A372: 46137 | B372: CSI-03664 | C372: APC DISTRIBUTION - VALENCIA | D372: DOMBF-1L | E372: {=IF(D372="", "", XLOOKUP(D372, 'MASTER ITEM LIST'!A:A, 'MASTER ITEM LIST'!B:B, ""))} -> DOMINO BODY FILTER WITH HARDENER 1L | F372: STOCK IN | G372: 12 | H372: {=IFERROR(XLOOKUP(D372,'MASTER ITEM LIST'!A:A,'MASTER ITEM LIST'!D:D), "")} -> LITER | I372: 160 | J372: =IF(G372="", "",G372*I372) -> 1920
A373: 46137 | B373: CSI-03664 | C373: APC DISTRIBUTION - VALENCIA | D373: HS-1L | E373: {=IF(D373="", "", XLOOKUP(D373, 'MASTER ITEM LIST'!A:A, 'MASTER ITEM LIST'!B:B, ""))} -> NIPPON HS FILLER 1L | F373: STOCK IN | G373: 12 | H373: {=IFERROR(XLOOKUP(D373,'MASTER ITEM LIST'!A:A,'MASTER ITEM LIST'!D:D), "")} -> LITER | I373: 720 | J373: =IF(G373="", "",G373*I373) -> 8640
...

Sheet INVENTORY REPORT
A1: ITEM CODE | B1: DESCRIPTION | C1: COST | D1: UNIT | E1: AVAILABLE STOCKS | F1: STOCK OUT | G1: STOCK IN
A2: =IFERROR(__xludf.DUMMYFUNCTION("FILTER('MASTER ITEM LIST'!A2:E1296, 'MASTER ITEM LIST'!A2:A1296 <> """")"),"ROS-633") -> ROS-633 | B2: =IFERROR(__xludf.DUMMYFUNCTION("""COMPUTED_VALUE"""),"RAIN OR SHINE CHOCOLATE BROWN 4L") -> RAIN OR SHINE CHOCOLATE BROWN 4L | C2: =IFERROR(__xludf.DUMMYFUNCTION("""COMPUTED_VALUE"""),665.0) -> 665 | D2: =IFERROR(__xludf.DUMMYFUNCTION("""COMPUTED_VALUE"""),"GALON") -> GALON | E2: =IFERROR(__xludf.DUMMYFUNCTION("""COMPUTED_VALUE"""),0.0) -> 0 | F2: =SUMIF(SALES!D:D, A2, SALES!H:H) + SUMIFS('STOCK IN TRANSFER'!G:G, 'STOCK IN TRANSFER'!D:D, A2, 'STOCK IN TRANSFER'!F:F, "TRANSFER") + SUMIFS('STOCK IN TRANSFER'!G:G, 'STOCK IN TRANSFER'!D:D, A2, 'STOCK IN TRANSFER'!F:F, "ADJUSTMENT (-)") -> 0.25 | G2: =SUMIFS('STOCK IN TRANSFER'!G:G, 'STOCK IN TRANSFER'!D:D, A2, 'STOCK IN TRANSFER'!F:F, "STOCK IN") + SUMIFS('STOCK IN TRANSFER'!G:G, 'STOCK IN TRANSFER'!D:D, A2, 'STOCK IN TRANSFER'!F:F, "ADJUSTMENT (+)") -> 0.25
A3: =IFERROR(__xludf.DUMMYFUNCTION("""COMPUTED_VALUE"""),"ROSCB-1L") -> ROSCB-1L | B3: =IFERROR(__xludf.DUMMYFUNCTION("""COMPUTED_VALUE"""),"RAIN OR SHINE CHOCOLATE BROWN 1L") -> RAIN OR SHINE CHOCOLATE BROWN 1L | C3: =IFERROR(__xludf.DUMMYFUNCTION("""COMPUTED_VALUE"""),0.0) -> 0 | D3: =IFERROR(__xludf.DUMMYFUNCTION("""COMPUTED_VALUE"""),"LITER") -> LITER | E3: =IFERROR(__xludf.DUMMYFUNCTION("""COMPUTED_VALUE"""),0.0) -> 0 | F3: =SUMIF(SALES!D:D, A3, SALES!H:H) + SUMIFS('STOCK IN TRANSFER'!G:G, 'STOCK IN TRANSFER'!D:D, A3, 'STOCK IN TRANSFER'!F:F, "TRANSFER") + SUMIFS('STOCK IN TRANSFER'!G:G, 'STOCK IN TRANSFER'!D:D, A3, 'STOCK IN TRANSFER'!F:F, "ADJUSTMENT (-)") -> 1 | G3: =SUMIFS('STOCK IN TRANSFER'!G:G, 'STOCK IN TRANSFER'!D:D, A3, 'STOCK IN TRANSFER'!F:F, "STOCK IN") + SUMIFS('STOCK IN TRANSFER'!G:G, 'STOCK IN TRANSFER'!D:D, A3, 'STOCK IN TRANSFER'!F:F, "ADJUSTMENT (+)") -> 1
A4: =IFERROR(__xludf.DUMMYFUNCTION("""COMPUTED_VALUE"""),"ROS-701") -> ROS-701 | B4: =IFERROR(__xludf.DUMMYFUNCTION("""COMPUTED_VALUE"""),"RAIN OR SHINE BAGUIO GREEN 4L") -> RAIN OR SHINE BAGUIO GREEN 4L | C4: =IFERROR(__xludf.DUMMYFUNCTION("""COMPUTED_VALUE"""),665.0) -> 665 | D4: =IFERROR(__xludf.DUMMYFUNCTION("""COMPUTED_VALUE"""),"GALON") -> GALON | E4: =IFERROR(__xludf.DUMMYFUNCTION("""COMPUTED_VALUE"""),0.0) -> 0 | F4: =SUMIF(SALES!D:D, A4, SALES!H:H) + SUMIFS('STOCK IN TRANSFER'!G:G, 'STOCK IN TRANSFER'!D:D, A4, 'STOCK IN TRANSFER'!F:F, "TRANSFER") + SUMIFS('STOCK IN TRANSFER'!G:G, 'STOCK IN TRANSFER'!D:D, A4, 'STOCK IN TRANSFER'!F:F, "ADJUSTMENT (-)") -> 6 | G4: =SUMIFS('STOCK IN TRANSFER'!G:G, 'STOCK IN TRANSFER'!D:D, A4, 'STOCK IN TRANSFER'!F:F, "STOCK IN") + SUMIFS('STOCK IN TRANSFER'!G:G, 'STOCK IN TRANSFER'!D:D, A4, 'STOCK IN TRANSFER'!F:F, "ADJUSTMENT (+)") -> 6
A5: =IFERROR(__xludf.DUMMYFUNCTION("""COMPUTED_VALUE"""),"POLYGTHIN-4L") -> POLYGTHIN-4L | B5: =IFERROR(__xludf.DUMMYFUNCTION("""COMPUTED_VALUE"""),"POLYGLOSS URETHANE THINNER 4L") -> POLYGLOSS URETHANE THINNER 4L | C5: =IFERROR(__xludf.DUMMYFUNCTION("""COMPUTED_VALUE"""),675.0) -> 675 | D5: =IFERROR(__xludf.DUMMYFUNCTION("""COMPUTED_VALUE"""),"GALON") -> GALON | E5: =IFERROR(__xludf.DUMMYFUNCTION("""COMPUTED_VALUE"""),0.0) -> 0 | F5: =SUMIF(SALES!D:D, A5, SALES!H:H) + SUMIFS('STOCK IN TRANSFER'!G:G, 'STOCK IN TRANSFER'!D:D, A5, 'STOCK IN TRANSFER'!F:F, "TRANSFER") + SUMIFS('STOCK IN TRANSFER'!G:G, 'STOCK IN TRANSFER'!D:D, A5, 'STOCK IN TRANSFER'!F:F, "ADJUSTMENT (-)") -> 9.75 | G5: =SUMIFS('STOCK IN TRANSFER'!G:G, 'STOCK IN TRANSFER'!D:D, A5, 'STOCK IN TRANSFER'!F:F, "STOCK IN") + SUMIFS('STOCK IN TRANSFER'!G:G, 'STOCK IN TRANSFER'!D:D, A5, 'STOCK IN TRANSFER'!F:F, "ADJUSTMENT (+)") -> 9.75
A6: =IFERROR(__xludf.DUMMYFUNCTION("""COMPUTED_VALUE"""),"PGTB-4L") -> PGTB-4L | B6: =IFERROR(__xludf.DUMMYFUNCTION("""COMPUTED_VALUE"""),"POLYGLOSS PU PHTHALO BLUE 4L") -> POLYGLOSS PU PHTHALO BLUE 4L | C6: =IFERROR(__xludf.DUMMYFUNCTION("""COMPUTED_VALUE"""),1883.0) -> 1883 | D6: =IFERROR(__xludf.DUMMYFUNCTION("""COMPUTED_VALUE"""),"GALON") -> GALON | E6: =IFERROR(__xludf.DUMMYFUNCTION("""COMPUTED_VALUE"""),0.0) -> 0 | F6: =SUMIF(SALES!D:D, A6, SALES!H:H) + SUMIFS('STOCK IN TRANSFER'!G:G, 'STOCK IN TRANSFER'!D:D, A6, 'STOCK IN TRANSFER'!F:F, "TRANSFER") + SUMIFS('STOCK IN TRANSFER'!G:G, 'STOCK IN TRANSFER'!D:D, A6, 'STOCK IN TRANSFER'!F:F, "ADJUSTMENT (-)") -> 0.25 | G6: =SUMIFS('STOCK IN TRANSFER'!G:G, 'STOCK IN TRANSFER'!D:D, A6, 'STOCK IN TRANSFER'!F:F, "STOCK IN") + SUMIFS('STOCK IN TRANSFER'!G:G, 'STOCK IN TRANSFER'!D:D, A6, 'STOCK IN TRANSFER'!F:F, "ADJUSTMENT (+)") -> 0.25
A7: =IFERROR(__xludf.DUMMYFUNCTION("""COMPUTED_VALUE"""),"PGMF-4L") -> PGMF-4L | B7: =IFERROR(__xludf.DUMMYFUNCTION("""COMPUTED_VALUE"""),"POLYGLOSS PU MICA RED FINE 4L") -> POLYGLOSS PU MICA RED FINE 4L | C7: =IFERROR(__xludf.DUMMYFUNCTION("""COMPUTED_VALUE"""),2822.0) -> 2822 | D7: =IFERROR(__xludf.DUMMYFUNCTION("""COMPUTED_VALUE"""),"GALON") -> GALON | E7: =IFERROR(__xludf.DUMMYFUNCTION("""COMPUTED_VALUE"""),0.0) -> 0 | F7: =SUMIF(SALES!D:D, A7, SALES!H:H) + SUMIFS('STOCK IN TRANSFER'!G:G, 'STOCK IN TRANSFER'!D:D, A7, 'STOCK IN TRANSFER'!F:F, "TRANSFER") + SUMIFS('STOCK IN TRANSFER'!G:G, 'STOCK IN TRANSFER'!D:D, A7, 'STOCK IN TRANSFER'!F:F, "ADJUSTMENT (-)") -> 0.5 | G7: =SUMIFS('STOCK IN TRANSFER'!G:G, 'STOCK IN TRANSFER'!D:D, A7, 'STOCK IN TRANSFER'!F:F, "STOCK IN") + SUMIFS('STOCK IN TRANSFER'!G:G, 'STOCK IN TRANSFER'!D:D, A7, 'STOCK IN TRANSFER'!F:F, "ADJUSTMENT (+)") -> 0.5
A8: =IFERROR(__xludf.DUMMYFUNCTION("""COMPUTED_VALUE"""),"PGMC-4L") -> PGMC-4L | B8: =IFERROR(__xludf.DUMMYFUNCTION("""COMPUTED_VALUE"""),"POLYGLOSS PU METALLIC COARSE 4L") -> POLYGLOSS PU METALLIC COARSE 4L | C8: =IFERROR(__xludf.DUMMYFUNCTION("""COMPUTED_VALUE"""),1743.0) -> 1743 | D8: =IFERROR(__xludf.DUMMYFUNCTION("""COMPUTED_VALUE"""),"GALON") -> GALON | E8: =IFERROR(__xludf.DUMMYFUNCTION("""COMPUTED_VALUE"""),0.0) -> 0 | F8: =SUMIF(SALES!D:D, A8, SALES!H:H) + SUMIFS('STOCK IN TRANSFER'!G:G, 'STOCK IN TRANSFER'!D:D, A8, 'STOCK IN TRANSFER'!F:F, "TRANSFER") + SUMIFS('STOCK IN TRANSFER'!G:G, 'STOCK IN TRANSFER'!D:D, A8, 'STOCK IN TRANSFER'!F:F, "ADJUSTMENT (-)") -> 1.0625 | G8: =SUMIFS('STOCK IN TRANSFER'!G:G, 'STOCK IN TRANSFER'!D:D, A8, 'STOCK IN TRANSFER'!F:F, "STOCK IN") + SUMIFS('STOCK IN TRANSFER'!G:G, 'STOCK IN TRANSFER'!D:D, A8, 'STOCK IN TRANSFER'!F:F, "ADJUSTMENT (+)") -> 1.0625
A9: =IFERROR(__xludf.DUMMYFUNCTION("""COMPUTED_VALUE"""),"PGJB-4L") -> PGJB-4L | B9: =IFERROR(__xludf.DUMMYFUNCTION("""COMPUTED_VALUE"""),"POLYGLOSS PU JET BLACK 4L") -> POLYGLOSS PU JET BLACK 4L | C9: =IFERROR(__xludf.DUMMYFUNCTION("""COMPUTED_VALUE"""),1828.0) -> 1828 | D9: =IFERROR(__xludf.DUMMYFUNCTION("""COMPUTED_VALUE"""),"GALON") -> GALON | E9: =IFERROR(__xludf.DUMMYFUNCTION("""COMPUTED_VALUE"""),0.0) -> 0 | F9: =SUMIF(SALES!D:D, A9, SALES!H:H) + SUMIFS('STOCK IN TRANSFER'!G:G, 'STOCK IN TRANSFER'!D:D, A9, 'STOCK IN TRANSFER'!F:F, "TRANSFER") + SUMIFS('STOCK IN TRANSFER'!G:G, 'STOCK IN TRANSFER'!D:D, A9, 'STOCK IN TRANSFER'!F:F, "ADJUSTMENT (-)") -> 2.625 | G9: =SUMIFS('STOCK IN TRANSFER'!G:G, 'STOCK IN TRANSFER'!D:D, A9, 'STOCK IN TRANSFER'!F:F, "STOCK IN") + SUMIFS('STOCK IN TRANSFER'!G:G, 'STOCK IN TRANSFER'!D:D, A9, 'STOCK IN TRANSFER'!F:F, "ADJUSTMENT (+)") -> 2.625
